<?xml version='1.0' encoding='utf-8'?>
<robot name="adam_sp">
  <link name="pelvis">
    <inertial>
      <origin xyz="-0.00034724 0.00000000 -0.00735759" rpy="0 0 0" />
      <mass value="10.35646604" />
      <inertia ixx="0.06211831" ixy="-0.00000103" ixz="-0.00007613" iyy="0.03451514" iyz="0.00000020" izz="0.06877943" />
    </inertial>
    <visual>
      <origin xyz="0 0 0" rpy="0 0 0" />
      <geometry>
        <mesh filename="../meshes/pelvis.STL" />
      </geometry>
      <material name="">
        <color rgba="0.752941176470588 0.752941176470588 0.752941176470588 1" />
      </material>
    </visual>
    <collision>
      <origin xyz="0 0 0" rpy="0 0 0" />
      <geometry>
        <mesh filename="../meshes/pelvis.STL" />
      </geometry>
    </collision>
  </link>
  <joint name="imu_joint" type="fixed">
    <parent link="pelvis" />
    <child link="imu_link" />
    <origin rpy="0 0 0" xyz="0 0 0" />
  </joint>
  <link name="imu_link">
    <inertial>
      <mass value="0.001" />
      <origin rpy="0 0 0" xyz="0 0 0" />
      <inertia ixx="0.0001" ixy="0" ixz="0" iyy="0.0001" iyz="0" izz="0.0001" />
    </inertial>
  </link>
  <link name="hipPitchLeft">
    <inertial>
      <origin xyz="-0.05660220 0.05761439 -0.00077159" rpy="0 0 0" />
      <mass value="2.23379987" />
      <inertia ixx="0.00362189" ixy="-0.00107609" ixz="0.00002179" iyy="0.00439139" iyz="0.00004441" izz="0.00515496" />
    </inertial>
    <visual>
      <origin xyz="0 0 0" rpy="0 0 0" />
      <geometry>
        <mesh filename="../meshes/hipPitchLeft.STL" />
      </geometry>
      <material name="">
        <color rgba="0.752941176470588 0.752941176470588 0.752941176470588 1" />
      </material>
    </visual>
    <collision>
      <origin xyz="0 0 0" rpy="0 0 0" />
      <geometry>
        <mesh filename="../meshes/hipPitchLeft.STL" />
      </geometry>
    </collision>
  </link>
  <joint name="hipPitch_Left" type="revolute">
    <origin xyz="0 0.0961924921295064 -0.0332411879418571" rpy="-0.610865238197473 0 0" />
    <parent link="pelvis" />
    <child link="hipPitchLeft" />
    <axis xyz="0 1 0" />
    <limit lower="-2.164" upper="2.164" effort="230" velocity="15" />
  </joint>
  <link name="hipRollLeft">
    <inertial>
      <origin xyz="0.03924162 0.00004107 -0.01032916" rpy="0 0 0" />
      <mass value="1.35107789" />
      <inertia ixx="0.00122242" ixy="-0.00000463" ixz="-0.00007104" iyy="0.00129116" iyz="-0.00000767" izz="0.00138754" />
    </inertial>
    <visual>
      <origin xyz="0 0 0" rpy="0 0 0" />
      <geometry>
        <mesh filename="../meshes/hipRollLeft.STL" />
      </geometry>
      <material name="">
        <color rgba="0.752941176470588 0.752941176470588 0.752941176470588 1" />
      </material>
    </visual>
    <collision>
      <origin xyz="0 0 0" rpy="0 0 0" />
      <geometry>
        <mesh filename="../meshes/hipRollLeft.STL" />
      </geometry>
    </collision>
  </link>
  <joint name="hipRoll_Left" type="revolute">
    <origin xyz="-0.0254999999999983 0.0690000000000026 0" rpy="0.610865238197473 0 0" />
    <parent link="hipPitchLeft" />
    <child link="hipRollLeft" />
    <axis xyz="1 0 0" />
    <limit lower="-0.733" upper="1.605" effort="160" velocity="8" />
  </joint>
  <link name="thighLeft">
    <inertial>
      <origin xyz="0.00244052 -0.00866423 -0.13433631" rpy="0 0 0" />
      <mass value="6.43432838" />
      <inertia ixx="0.05827182" ixy="-0.00024775" ixz="-0.00135721" iyy="0.06333936" iyz="0.00551470" izz="0.01331159" />
    </inertial>
    <visual>
      <origin xyz="0 0 0" rpy="0 0 0" />
      <geometry>
        <mesh filename="../meshes/thighLeft.STL" />
      </geometry>
      <material name="">
        <color rgba="0.752941176470588 0.752941176470588 0.752941176470588 1" />
      </material>
    </visual>
    <collision>
      <origin xyz="0 0 0" rpy="0 0 0" />
      <geometry>
        <mesh filename="../meshes/thighLeft.STL" />
      </geometry>
    </collision>
  </link>
  <joint name="hipYaw_Left" type="revolute">
    <origin xyz="0.0440000071360198 0 -0.0524999940193389" rpy="0 0 0" />
    <parent link="hipRollLeft" />
    <child link="thighLeft" />
    <axis xyz="0 0 1" />
    <limit lower="-0.785" upper="0.785" effort="105" velocity="8" />
  </joint>
  <link name="shinLeft">
    <inertial>
      <origin xyz="-0.00053135 0.00081959 -0.14538124" rpy="0 0 0" />
      <mass value="2.25363003" />
      <inertia ixx="0.02151350" ixy="-0.00001764" ixz="0.00032260" iyy="0.02158746" iyz="0.00004329" izz="0.00136992" />
    </inertial>
    <visual>
      <origin xyz="0 0 0" rpy="0 0 0" />
      <geometry>
        <mesh filename="../meshes/shinLeft.STL" />
      </geometry>
      <material name="">
        <color rgba="0.752941176470588 0.752941176470588 0.752941176470588 1" />
      </material>
    </visual>
    <collision>
      <origin xyz="0 0 0" rpy="0 0 0" />
      <geometry>
        <mesh filename="../meshes/shinLeft.STL" />
      </geometry>
    </collision>
  </link>
  <joint name="kneePitch_Left" type="revolute">
    <origin xyz="0 -0.0354999999998497 -0.369000000000099" rpy="0 0 0" />
    <parent link="thighLeft" />
    <child link="shinLeft" />
    <axis xyz="0 1 0" />
    <limit lower="0.052" upper="2.391" effort="230" velocity="15" />
  </joint>
  <link name="anklePitchLeft">
    <inertial>
      <origin xyz="0.00000000 0.00000000 0.00000000" rpy="0 0 0" />
      <mass value="0.03014230" />
      <inertia ixx="0.00000314" ixy="0.00000000" ixz="0.00000000" iyy="0.00000314" iyz="0.00000000" izz="0.00000204" />
    </inertial>
    <visual>
      <origin xyz="0 0 0" rpy="0 0 0" />
      <geometry>
        <mesh filename="../meshes/anklePitchLeft.STL" />
      </geometry>
      <material name="">
        <color rgba="1 1 1 1" />
      </material>
    </visual>
    <collision>
      <origin xyz="0 0 0" rpy="0 0 0" />
      <geometry>
        <mesh filename="../meshes/anklePitchLeft.STL" />
      </geometry>
    </collision>
  </link>
  <joint name="anklePitch_Left" type="revolute">
    <origin xyz="0 0 -0.36999999999995" rpy="0 0 0" />
    <parent link="shinLeft" />
    <child link="anklePitchLeft" />
    <axis xyz="0 1 0" />
    <limit lower="-1.0" upper="0.35" effort="40" velocity="20" />
  </joint>
  <link name="toeLeft">
    <inertial>
      <origin xyz="0.03749965 -0.00004016 -0.04196743" rpy="0 0 0" />
      <mass value="0.63479601" />
      <inertia ixx="0.00045636" ixy="0.00001603" ixz="-0.00020108" iyy="0.00226894" iyz="0.00000180" izz="0.00231317" />
    </inertial>
    <visual>
      <origin xyz="0 0 0" rpy="0 0 0" />
      <geometry>
        <mesh filename="../meshes/toeLeft.STL" />
      </geometry>
      <material name="">
        <color rgba="0.752941176470588 0.752941176470588 0.752941176470588 1" />
      </material>
    </visual>
    <collision>
      <origin xyz="0 0 0" rpy="0 0 0" />
      <geometry>
        <mesh filename="../meshes/toeLeft.STL" />
      </geometry>
    </collision>
  </link>
  <joint name="ankleRoll_Left" type="revolute">
    <origin xyz="0 0 0" rpy="0 0 0" />
    <parent link="anklePitchLeft" />
    <child link="toeLeft" />
    <axis xyz="1 0 0" />
    <limit lower="-0.3491" upper="0.3491" effort="12" velocity="20" />
  </joint>
  <link name="hipPitchRight">
    <inertial>
      <origin xyz="-0.05661792 -0.05759336 -0.00078211" rpy="0 0 0" />
      <mass value="2.23477271" />
      <inertia ixx="0.00362315" ixy="0.00107435" ixz="0.00002228" iyy="0.00439419" iyz="-0.00004505" izz="0.00515804" />
    </inertial>
    <visual>
      <origin xyz="0 0 0" rpy="0 0 0" />
      <geometry>
        <mesh filename="../meshes/hipPitchRight.STL" />
      </geometry>
      <material name="">
        <color rgba="0.752941176470588 0.752941176470588 0.752941176470588 1" />
      </material>
    </visual>
    <collision>
      <origin xyz="0 0 0" rpy="0 0 0" />
      <geometry>
        <mesh filename="../meshes/hipPitchRight.STL" />
      </geometry>
    </collision>
  </link>
  <joint name="hipPitch_Right" type="revolute">
    <origin xyz="0 -0.0961924781696877 -0.0332412045786055" rpy="0.610865238197555 0 0" />
    <parent link="pelvis" />
    <child link="hipPitchRight" />
    <axis xyz="0 1 0" />
    <limit lower="-2.164" upper="2.164" effort="230" velocity="15" />
  </joint>
  <link name="hipRollRight">
    <inertial>
      <origin xyz="0.03925975 -0.00005814 -0.01032408" rpy="0 0 0" />
      <mass value="1.35169943" />
      <inertia ixx="0.00122275" ixy="0.00000501" ixz="-0.00007267" iyy="0.00129208" iyz="0.00000835" izz="0.00138861" />
    </inertial>
    <visual>
      <origin xyz="0 0 0" rpy="0 0 0" />
      <geometry>
        <mesh filename="../meshes/hipRollRight.STL" />
      </geometry>
      <material name="">
        <color rgba="0.752941176470588 0.752941176470588 0.752941176470588 1" />
      </material>
    </visual>
    <collision>
      <origin xyz="0 0 0" rpy="0 0 0" />
      <geometry>
        <mesh filename="../meshes/hipRollRight.STL" />
      </geometry>
    </collision>
  </link>
  <joint name="hipRoll_Right" type="revolute">
    <origin xyz="-0.0254999999999981 -0.0689999999999357 0" rpy="-0.610865238197555 0 0" />
    <parent link="hipPitchRight" />
    <child link="hipRollRight" />
    <axis xyz="1 0 0" />
    <limit lower="-1.605" upper="0.733" effort="160" velocity="8" />
  </joint>
  <link name="thighRight">
    <inertial>
      <origin xyz="0.00245598 0.00865064 -0.13433188" rpy="0 0 0" />
      <mass value="6.43084152" />
      <inertia ixx="0.05823192" ixy="0.00024481" ixz="-0.00134046" iyy="0.06331326" iyz="-0.00551858" izz="0.01331917" />
    </inertial>
    <visual>
      <origin xyz="0 0 0" rpy="0 0 0" />
      <geometry>
        <mesh filename="../meshes/thighRight.STL" />
      </geometry>
      <material name="">
        <color rgba="0.752941176470588 0.752941176470588 0.752941176470588 1" />
      </material>
    </visual>
    <collision>
      <origin xyz="0 0 0" rpy="0 0 0" />
      <geometry>
        <mesh filename="../meshes/thighRight.STL" />
      </geometry>
    </collision>
  </link>
  <joint name="hipYaw_Right" type="revolute">
    <origin xyz="0.0439999724402559 0 -0.0525000230976866" rpy="0 0 0" />
    <parent link="hipRollRight" />
    <child link="thighRight" />
    <axis xyz="0 0 1" />
    <limit lower="-0.785" upper="0.785" effort="105" velocity="8" />
  </joint>
  <link name="shinRight">
    <inertial>
      <origin xyz="-0.00052844 -0.00082152 -0.14533361" rpy="0 0 0" />
      <mass value="2.25459286" />
      <inertia ixx="0.02149493" ixy="0.00001649" ixz="0.00032142" iyy="0.02156785" iyz="-0.00004501" izz="0.00137005" />
    </inertial>
    <visual>
      <origin xyz="0 0 0" rpy="0 0 0" />
      <geometry>
        <mesh filename="../meshes/shinRight.STL" />
      </geometry>
      <material name="">
        <color rgba="0.752941176470588 0.752941176470588 0.752941176470588 1" />
      </material>
    </visual>
    <collision>
      <origin xyz="0 0 0" rpy="0 0 0" />
      <geometry>
        <mesh filename="../meshes/shinRight.STL" />
      </geometry>
    </collision>
  </link>
  <joint name="kneePitch_Right" type="revolute">
    <origin xyz="0 0.0354999999997395 -0.368999999999986" rpy="0 0 0" />
    <parent link="thighRight" />
    <child link="shinRight" />
    <axis xyz="0 1 0" />
    <limit lower="0.052" upper="2.391" effort="230" velocity="15" />
  </joint>
  <link name="anklePitchRight">
    <inertial>
      <origin xyz="0.00000000 0.00000000 0.00000000" rpy="0 0 0" />
      <mass value="0.03014230" />
      <inertia ixx="0.00000314" ixy="0.00000000" ixz="0.00000000" iyy="0.00000314" iyz="0.00000000" izz="0.00000204" />
    </inertial>
    <visual>
      <origin xyz="0 0 0" rpy="0 0 0" />
      <geometry>
        <mesh filename="../meshes/anklePitchRight.STL" />
      </geometry>
      <material name="">
        <color rgba="1 1 1 1" />
      </material>
    </visual>
    <collision>
      <origin xyz="0 0 0" rpy="0 0 0" />
      <geometry>
        <mesh filename="../meshes/anklePitchRight.STL" />
      </geometry>
    </collision>
  </link>
  <joint name="anklePitch_Right" type="revolute">
    <origin xyz="0 0 -0.369999999999911" rpy="0 0 0" />
    <parent link="shinRight" />
    <child link="anklePitchRight" />
    <axis xyz="0 1 0" />
    <limit lower="-1.0" upper="0.35" effort="40" velocity="20" />
  </joint>
  <link name="toeRight">
    <inertial>
      <origin xyz="0.03750226 0.00004002 -0.04196714" rpy="0 0 0" />
      <mass value="0.63480789" />
      <inertia ixx="0.00045639" ixy="-0.00001603" ixz="-0.00020109" iyy="0.00226894" iyz="-0.00000181" izz="0.00231317" />
    </inertial>
    <visual>
      <origin xyz="0 0 0" rpy="0 0 0" />
      <geometry>
        <mesh filename="../meshes/toeRight.STL" />
      </geometry>
      <material name="">
        <color rgba="0.752941176470588 0.752941176470588 0.752941176470588 1" />
      </material>
    </visual>
    <collision>
      <origin xyz="0 0 0" rpy="0 0 0" />
      <geometry>
        <mesh filename="../meshes/toeRight.STL" />
      </geometry>
    </collision>
  </link>
  <joint name="ankleRoll_Right" type="revolute">
    <origin xyz="0 0 0" rpy="0 0 0" />
    <parent link="anklePitchRight" />
    <child link="toeRight" />
    <axis xyz="1 0 0" />
    <limit lower="-0.3491" upper="0.3491" effort="12" velocity="20" />
  </joint>
  <link name="waistRoll_link">
    <inertial>
      <origin xyz="0.00093826 0.00093832 0.03999995" rpy="0 0 0" />
      <mass value="2.36268465" />
      <inertia ixx="0.00543041" ixy="-0.00000171" ixz="-0.00006791" iyy="0.00543044" iyz="0.00006793" izz="0.00184993" />
    </inertial>
    <visual>
      <origin xyz="0 0 0" rpy="0 0 0" />
      <geometry>
        <mesh filename="../meshes/waistRoll.STL" />
      </geometry>
      <material name="">
        <color rgba="1 1 1 1" />
      </material>
    </visual>
    <collision>
      <origin xyz="0 0 0" rpy="0 0 0" />
      <geometry>
        <mesh filename="../meshes/waistRoll.STL" />
      </geometry>
    </collision>
  </link>
  <joint name="waistRoll" type="revolute">
    <origin xyz="0 0 0.0440000000007929" rpy="0 0 0" />
    <parent link="pelvis" />
    <child link="waistRoll_link" />
    <axis xyz="1 0 0" />
    <limit lower="-0.279" upper="0.279" effort="110" velocity="8" />
  </joint>
  <link name="waistPitch_link">
    <inertial>
      <origin xyz="-0.00008401 0.00189362 0.02548321" rpy="0 0 0" />
      <mass value="0.56353776" />
      <inertia ixx="0.00151470" ixy="0.00001037" ixz="0.00000444" iyy="0.00067279" iyz="-0.00001192" izz="0.00155907" />
    </inertial>
    <visual>
      <origin xyz="0 0 0" rpy="0 0 0" />
      <geometry>
        <mesh filename="../meshes/waistPitch.STL" />
      </geometry>
      <material name="">
        <color rgba="0.752941176470588 0.752941176470588 0.752941176470588 1" />
      </material>
    </visual>
    <collision>
      <origin xyz="0 0 0" rpy="0 0 0" />
      <geometry>
        <mesh filename="../meshes/waistPitch.STL" />
      </geometry>
    </collision>
  </link>
  <joint name="waistPitch" type="revolute">
    <origin xyz="0 0 0.08" rpy="0 0 0" />
    <parent link="waistRoll_link" />
    <child link="waistPitch_link" />
    <axis xyz="0 1 0" />
    <limit lower="-0.663" upper="1.361" effort="110" velocity="8" />
  </joint>
  <link name="torso">
    <inertial>
      <origin xyz="-0.00003545 0.00048442 0.18592394" rpy="0 0 0" />
      <mass value="13.46342537" />
      <inertia ixx="0.21136563" ixy="-0.00036520" ixz="0.00322885" iyy="0.16865137" iyz="-0.00023237" izz="0.07708497" />
    </inertial>
    <visual>
      <origin xyz="0 0 0" rpy="0 0 0" />
      <geometry>
        <mesh filename="../meshes/torso.STL" />
      </geometry>
      <material name="">
        <color rgba="0.752941176470588 0.752941176470588 0.752941176470588 1" />
      </material>
    </visual>
    <collision>
      <origin xyz="0 0 0" rpy="0 0 0" />
      <geometry>
        <mesh filename="../meshes/torso.STL" />
      </geometry>
    </collision>
  </link>
  <joint name="waistYaw" type="revolute">
    <origin xyz="0 0.000500000000007081 0.05299999999999" rpy="0 0 0" />
    <parent link="waistPitch_link" />
    <child link="torso" />
    <axis xyz="0 0 1" />
    <limit lower="-0.829" upper="0.829" effort="110" velocity="8" />
  </joint>
  <link name="shoulderPitchLeft">
    <inertial>
      <origin xyz="0.00542694 0.02689874 0.00010792" rpy="0 0 0" />
      <mass value="0.21614811" />
      <inertia ixx="0.00019044" ixy="0.00002059" ixz="-0.00000121" iyy="0.00031955" iyz="-0.00000016" izz="0.00038064" />
    </inertial>
    <visual>
      <origin xyz="0 0 0" rpy="0 0 0" />
      <geometry>
        <mesh filename="../meshes/shoulderPitchLeft.STL" />
      </geometry>
      <material name="">
        <color rgba="1 1 1 1" />
      </material>
    </visual>
    <collision>
      <origin xyz="0 0 0" rpy="0 0 0" />
      <geometry>
        <mesh filename="../meshes/shoulderPitchLeft.STL" />
      </geometry>
    </collision>
  </link>
  <joint name="shoulderPitch_Left" type="revolute">
    <origin xyz="0 0.165093970689425 0.259229560594865" rpy="0.349065850393456 0 0" />
    <parent link="torso" />
    <child link="shoulderPitchLeft" />
    <axis xyz="0 1 0" />
    <limit lower="-3.613" upper="2.042" effort="65" velocity="8" />
  </joint>
  <link name="shoulderRollLeft">
    <inertial>
      <origin xyz="-0.03437328 0.00962154 -0.01544556" rpy="0 0 0" />
      <mass value="1.07881773" />
      <inertia ixx="0.00167078" ixy="-0.00000554" ixz="0.00001969" iyy="0.00140477" iyz="-0.00043555" izz="0.00092612" />
    </inertial>
    <visual>
      <origin xyz="0 0 0" rpy="0 0 0" />
      <geometry>
        <mesh filename="../meshes/shoulderRollLeft.STL" />
      </geometry>
      <material name="">
        <color rgba="0.752941176470588 0.752941176470588 0.752941176470588 1" />
      </material>
    </visual>
    <collision>
      <origin xyz="0 0 0" rpy="0 0 0" />
      <geometry>
        <mesh filename="../meshes/shoulderRollLeft.STL" />
      </geometry>
    </collision>
  </link>
  <joint name="shoulderRoll_Left" type="revolute">
    <origin xyz="0.036199999996826 0.0434999999975074 0" rpy="-0.349065850393456 0 0" />
    <parent link="shoulderPitchLeft" />
    <child link="shoulderRollLeft" />
    <axis xyz="1 0 0" />
    <limit lower="-0.628" upper="2.793" effort="65" velocity="8" />
  </joint>
  <link name="shoulderYawLeft">
    <inertial>
      <origin xyz="-0.00051421 -0.00044442 -0.06193283" rpy="0 0 0" />
      <mass value="0.90142027" />
      <inertia ixx="0.00328558" ixy="0.00000020" ixz="0.00004743" iyy="0.00317226" iyz="0.00004945" izz="0.00057589" />
    </inertial>
    <visual>
      <origin xyz="0 0 0" rpy="0 0 0" />
      <geometry>
        <mesh filename="../meshes/shoulderYawLeft.STL" />
      </geometry>
      <material name="">
        <color rgba="1 1 1 1" />
      </material>
    </visual>
    <collision>
      <origin xyz="0 0 0" rpy="0 0 0" />
      <geometry>
        <mesh filename="../meshes/shoulderYawLeft.STL" />
      </geometry>
    </collision>
  </link>
  <joint name="shoulderYaw_Left" type="revolute">
    <origin xyz="-0.0361999999622004 0.0340000000110588 -0.0796999999903454" rpy="0 0 0" />
    <parent link="shoulderRollLeft" />
    <child link="shoulderYawLeft" />
    <axis xyz="0 0 1" />
    <limit lower="-2.583" upper="2.583" effort="65" velocity="8" />
  </joint>
  <link name="elbowLeft">
    <inertial>
      <origin xyz="-0.01407267 0.02929713 -0.02534726" rpy="0 0 0" />
      <mass value="0.91770702" />
      <inertia ixx="0.00096270" ixy="0.00001056" ixz="0.00026207" iyy="0.00110409" iyz="0.00002163" izz="0.00059478" />
    </inertial>
    <visual>
      <origin xyz="0 0 0" rpy="0 0 0" />
      <geometry>
        <mesh filename="../meshes/elbowLeft.STL" />
      </geometry>
      <material name="">
        <color rgba="0.752941176470588 0.752941176470588 0.752941176470588 1" />
      </material>
    </visual>
    <collision>
      <origin xyz="0 0 0" rpy="0 0 0" />
      <geometry>
        <mesh filename="../meshes/elbowLeft.STL" />
      </geometry>
    </collision>
  </link>
  <joint name="elbow_Left" type="revolute">
    <origin xyz="0 -0.0285000000009982 -0.182950000001738" rpy="0 0 0" />
    <parent link="shoulderYawLeft" />
    <child link="elbowLeft" />
    <axis xyz="0 1 0" />
    <limit lower="-2.496" upper="0.209" effort="30" velocity="8" />
  </joint>
  <link name="wristYawLeft">
    <inertial>
      <origin xyz="-0.00204137 0.00010627 -0.09216777" rpy="0 0 0" />
      <mass value="0.95587869" />
      <inertia ixx="0.00256138" ixy="-0.00000268" ixz="0.00003060" iyy="0.00250125" iyz="-0.00002660" izz="0.00055105" />
    </inertial>
    <visual>
      <origin xyz="0 0 0" rpy="0 0 0" />
      <geometry>
        <mesh filename="../meshes/wristYawLeft.STL" />
      </geometry>
      <material name="">
        <color rgba="0.752941176470588 0.752941176470588 0.752941176470588 1" />
      </material>
    </visual>
    <collision>
      <origin xyz="0 0 0" rpy="0 0 0" />
      <geometry>
        <mesh filename="../meshes/wristYawLeft.STL" />
      </geometry>
    </collision>
  </link>
  <joint name="wristYaw_Left" type="fixed">
    <origin xyz="-0.0250000000083053 0.028499999997574 -0.0728999999980683" rpy="0 0 0" />
    <parent link="elbowLeft" />
    <child link="wristYawLeft" />
    <axis xyz="0 0 1" />
    <limit lower="-2.67" upper="2.67" effort="6.4" velocity="5" />
  </joint>
  <link name="wristPitchLeft">
    <inertial>
      <origin xyz="-0.00017582 0.00166098 -0.00002773" rpy="0 0 0" />
      <mass value="0.11963454" />
      <inertia ixx="0.00003359" ixy="0.00000002" ixz="0.00000000" iyy="0.00002690" iyz="-0.00000005" izz="0.00003977" />
    </inertial>
    <visual>
      <origin xyz="0 0 0" rpy="0 0 0" />
      <geometry>
        <mesh filename="../meshes/wristPitchLeft.STL" />
      </geometry>
      <material name="">
        <color rgba="1 1 1 1" />
      </material>
    </visual>
    <collision>
      <origin xyz="0 0 0" rpy="0 0 0" />
      <geometry>
        <mesh filename="../meshes/wristPitchLeft.STL" />
      </geometry>
    </collision>
  </link>
  <joint name="wristPitch_Left" type="fixed">
    <origin xyz="0 0 -0.201699999999994" rpy="0 0 0" />
    <parent link="wristYawLeft" />
    <child link="wristPitchLeft" />
    <axis xyz="0 1 0" />
    <limit lower="-0.96" upper="0.96" effort="6.4" velocity="5" />
  </joint>
  <link name="wristRollLeft">
    <inertial>
      <origin xyz="-0.00027229 0.00864497 -0.06627017" rpy="0 0 0" />
      <mass value="0.35749661" />
      <inertia ixx="0.00032014" ixy="0.00001166" ixz="-0.00000403" iyy="0.00042954" iyz="-0.00002167" izz="0.00018487" />
    </inertial>
    <visual>
      <origin xyz="0 0 0" rpy="0 0 0" />
      <geometry>
        <mesh filename="../meshes/wristRollLeft.STL" />
      </geometry>
      <material name="">
        <color rgba="0.752941176470588 0.752941176470588 0.752941176470588 1" />
      </material>
    </visual>
    <collision>
      <origin xyz="0 0 0" rpy="0 0 0" />
      <geometry>
        <mesh filename="../meshes/wristRollLeft.STL" />
      </geometry>
    </collision>
  </link>
  <joint name="wristRoll_Left" type="fixed">
    <origin xyz="0 0 0" rpy="0 0 0" />
    <parent link="wristPitchLeft" />
    <child link="wristRollLeft" />
    <axis xyz="1 0 0" />
    <limit lower="-0.96" upper="0.96" effort="6.4" velocity="5" />
  </joint>
  <link name="L_thumb_proximal_base">
    <inertial>
      <origin xyz="0.00431634 0.00026726 -0.00141885" rpy="0 0 0" />
      <mass value="0.00893190" />
      <inertia ixx="0.00000031" ixy="-0.00000008" ixz="-0.00000006" iyy="0.00000055" iyz="0.00000001" izz="0.00000046" />
    </inertial>
    <visual>
      <origin xyz="0 0 0" rpy="0 0 0" />
      <geometry>
        <mesh filename="../meshes/L_thumb_proximal_base.STL" />
      </geometry>
      <material name="">
        <color rgba="0.752941176470588 0.752941176470588 0.752941176470588 1" />
      </material>
    </visual>
    <collision>
      <origin xyz="0 0 0" rpy="0 0 0" />
      <geometry>
        <mesh filename="../meshes/L_thumb_proximal_base.STL" />
      </geometry>
    </collision>
  </link>
  <joint name="L_thumb_MCP_joint1" type="fixed">
    <origin xyz="0.0244999999969742 -0.0099999999982788 -0.0470000000019433" rpy="0 0 0" />
    <parent link="wristRollLeft" />
    <child link="L_thumb_proximal_base" />
    <axis xyz="0 0 -1" />
    <limit lower="0" upper="1.1" effort="1" velocity="1" />
  </joint>
  <link name="L_thumb_proximal">
    <inertial>
      <origin xyz="0.02369693 0.00000000 -0.01467236" rpy="0 0 0" />
      <mass value="0.06158427" />
      <inertia ixx="0.00001171" ixy="0.00000000" ixz="-0.00000575" iyy="0.00002013" iyz="0.00000000" izz="0.00001139" />
    </inertial>
    <visual>
      <origin xyz="0 0 0" rpy="0 0 0" />
      <geometry>
        <mesh filename="../meshes/L_thumb_proximal.STL" />
      </geometry>
      <material name="">
        <color rgba="0.752941176470588 0.752941176470588 0.752941176470588 1" />
      </material>
    </visual>
    <collision>
      <origin xyz="0 0 0" rpy="0 0 0" />
      <geometry>
        <mesh filename="../meshes/L_thumb_proximal.STL" />
      </geometry>
    </collision>
  </link>
  <joint name="L_thumb_MCP_joint2" type="fixed">
    <origin xyz="0.011954002456522 -0.00104967865057148 0" rpy="0 0 -0.0875851578962738" />
    <parent link="L_thumb_proximal_base" />
    <child link="L_thumb_proximal" />
    <axis xyz="0 1 0" />
    <limit lower="0" upper="0.5" effort="1" velocity="1" />
  </joint>
  <link name="L_thumb_intermediate">
    <inertial>
      <origin xyz="0.00973134 0.00000000 -0.00266466" rpy="0 0 0" />
      <mass value="0.01538337" />
      <inertia ixx="0.00000142" ixy="0.00000000" ixz="-0.00000039" iyy="0.00000172" iyz="0.00000000" izz="0.00000100" />
    </inertial>
    <visual>
      <origin xyz="0 0 0" rpy="0 0 0" />
      <geometry>
        <mesh filename="../meshes/L_thumb_intermediate.STL" />
      </geometry>
      <material name="">
        <color rgba="0.752941176470588 0.752941176470588 0.752941176470588 1" />
      </material>
    </visual>
    <collision>
      <origin xyz="0 0 0" rpy="0 0 0" />
      <geometry>
        <mesh filename="../meshes/L_thumb_intermediate.STL" />
      </geometry>
    </collision>
  </link>
  <joint name="L_thumb_PIP_joint" type="fixed">
    <origin xyz="0.0442885641132063 0 -0.0376632856876562" rpy="0 0 0" />
    <parent link="L_thumb_proximal" />
    <child link="L_thumb_intermediate" />
    <axis xyz="0 1 0" />
    <limit lower="0" upper="1" effort="1" velocity="1" />
  </joint>
  <link name="L_thumb_distal">
    <inertial>
      <origin xyz="0.00714221 -0.00000154 -0.00689404" rpy="0 0 0" />
      <mass value="0.01043740" />
      <inertia ixx="0.00000076" ixy="0.00000000" ixz="-0.00000020" iyy="0.00000086" iyz="0.00000000" izz="0.00000052" />
    </inertial>
    <visual>
      <origin xyz="0 0 0" rpy="0 0 0" />
      <geometry>
        <mesh filename="../meshes/L_thumb_distal.STL" />
      </geometry>
      <material name="">
        <color rgba="0.752941176470588 0.752941176470588 0.752941176470588 1" />
      </material>
    </visual>
    <collision>
      <origin xyz="0 0 0" rpy="0 0 0" />
      <geometry>
        <mesh filename="../meshes/L_thumb_distal.STL" />
      </geometry>
    </collision>
  </link>
  <joint name="L_thumb_DIP_joint" type="fixed">
    <origin xyz="0.0164679343341741 0 -0.0154614727230483" rpy="0 0 0" />
    <parent link="L_thumb_intermediate" />
    <child link="L_thumb_distal" />
    <axis xyz="0 1 0" />
    <limit lower="0" upper="1.2" effort="1" velocity="1" />
  </joint>
  <link name="L_index_proximal">
    <inertial>
      <origin xyz="0.00000000 0.00199817 -0.01311708" rpy="0 0 0" />
      <mass value="0.01454111" />
      <inertia ixx="0.00000195" ixy="0.00000000" ixz="0.00000000" iyy="0.00000195" iyz="0.00000002" izz="0.00000054" />
    </inertial>
    <visual>
      <origin xyz="0 0 0" rpy="0 0 0" />
      <geometry>
        <mesh filename="../meshes/L_index_proximal.STL" />
      </geometry>
      <material name="">
        <color rgba="0.752941176470588 0.752941176470588 0.752941176470588 1" />
      </material>
    </visual>
    <collision>
      <origin xyz="0 0 0" rpy="0 0 0" />
      <geometry>
        <mesh filename="../meshes/L_index_proximal.STL" />
      </geometry>
    </collision>
  </link>
  <joint name="L_index_MCP_joint" type="fixed">
    <origin xyz="0.0269420472022218 0.00950000000154763 -0.114975331627829" rpy="0 -0.0523598774782631 0" />
    <parent link="wristRollLeft" />
    <child link="L_index_proximal" />
    <axis xyz="-1 0 0" />
    <limit lower="0" upper="1.7" effort="1" velocity="1" />
  </joint>
  <link name="L_index_distal">
    <inertial>
      <origin xyz="0.00000000 0.00168954 -0.01536935" rpy="0 0 0" />
      <mass value="0.00905901" />
      <inertia ixx="0.00000173" ixy="0.00000000" ixz="0.00000000" iyy="0.00000168" iyz="0.00000025" izz="0.00000025" />
    </inertial>
    <visual>
      <origin xyz="0 0 0" rpy="0 0 0" />
      <geometry>
        <mesh filename="../meshes/L_index_distal.STL" />
      </geometry>
      <material name="">
        <color rgba="0.752941176470588 0.752941176470588 0.752941176470588 1" />
      </material>
    </visual>
    <collision>
      <origin xyz="0 0 0" rpy="0 0 0" />
      <geometry>
        <mesh filename="../meshes/L_index_distal.STL" />
      </geometry>
    </collision>
  </link>
  <joint name="L_index_DIP_joint" type="fixed">
    <origin xyz="0 -0.00111268989731944 -0.0319806491677784" rpy="0 0 0" />
    <parent link="L_index_proximal" />
    <child link="L_index_distal" />
    <axis xyz="-1 0 0" />
    <limit lower="0" upper="1.6" effort="1" velocity="1" />
  </joint>
  <link name="L_middle_proximal">
    <inertial>
      <origin xyz="0.00000000 0.00115546 -0.01334192" rpy="0 0 0" />
      <mass value="0.01313099" />
      <inertia ixx="0.00000194" ixy="0.00000000" ixz="0.00000000" iyy="0.00000193" iyz="0.00000010" izz="0.00000054" />
    </inertial>
    <visual>
      <origin xyz="0 0 0" rpy="0 0 0" />
      <geometry>
        <mesh filename="../meshes/L_middle_proximal.STL" />
      </geometry>
      <material name="">
        <color rgba="0.752941176470588 0.752941176470588 0.752941176470588 1" />
      </material>
    </visual>
    <collision>
      <origin xyz="0 0 0" rpy="0 0 0" />
      <geometry>
        <mesh filename="../meshes/L_middle_proximal.STL" />
      </geometry>
    </collision>
  </link>
  <joint name="L_middle_MCP_joint" type="fixed">
    <origin xyz="0.00799999998838565 0.0144999999999475 -0.128000000000728" rpy="0 0 0" />
    <parent link="wristRollLeft" />
    <child link="L_middle_proximal" />
    <axis xyz="-1 0 0" />
    <limit lower="0" upper="1.7" effort="1" velocity="1" />
  </joint>
  <link name="L_middle_distal">
    <inertial>
      <origin xyz="0.00000000 -0.00003933 -0.01546189" rpy="0 0 0" />
      <mass value="0.00905901" />
      <inertia ixx="0.00000173" ixy="0.00000000" ixz="0.00000000" iyy="0.00000161" iyz="0.00000040" izz="0.00000032" />
    </inertial>
    <visual>
      <origin xyz="0 0 0" rpy="0 0 0" />
      <geometry>
        <mesh filename="../meshes/L_middle_distal.STL" />
      </geometry>
      <material name="">
        <color rgba="0.752941176470588 0.752941176470588 0.752941176470588 1" />
      </material>
    </visual>
    <collision>
      <origin xyz="0 0 0" rpy="0 0 0" />
      <geometry>
        <mesh filename="../meshes/L_middle_distal.STL" />
      </geometry>
    </collision>
  </link>
  <joint name="L_middle_DIP_joint" type="fixed">
    <origin xyz="0 -0.00293735370583337 -0.0318649015879072" rpy="0 0 0" />
    <parent link="L_middle_proximal" />
    <child link="L_middle_distal" />
    <axis xyz="-1 0 0" />
    <limit lower="0" upper="1.6" effort="1" velocity="1" />
  </joint>
  <link name="L_ring_proximal">
    <inertial>
      <origin xyz="-0.00000395 0.00199338 -0.01313108" rpy="0 0 0" />
      <mass value="0.01454111" />
      <inertia ixx="0.00000195" ixy="0.00000000" ixz="0.00000000" iyy="0.00000195" iyz="0.00000002" izz="0.00000054" />
    </inertial>
    <visual>
      <origin xyz="0 0 0" rpy="0 0 0" />
      <geometry>
        <mesh filename="../meshes/L_ring_proximal.STL" />
      </geometry>
      <material name="">
        <color rgba="0.752941176470588 0.752941176470588 0.752941176470588 1" />
      </material>
    </visual>
    <collision>
      <origin xyz="0 0 0" rpy="0 0 0" />
      <geometry>
        <mesh filename="../meshes/L_ring_proximal.STL" />
      </geometry>
    </collision>
  </link>
  <joint name="L_ring_MCP_joint" type="fixed">
    <origin xyz="-0.0109420472229284 0.00949999999845705 -0.119975331624717" rpy="0 0.052359877641387 0" />
    <parent link="wristRollLeft" />
    <child link="L_ring_proximal" />
    <axis xyz="-1 0 0" />
    <limit lower="0" upper="1.7" effort="1" velocity="1" />
  </joint>
  <link name="L_ring_distal">
    <inertial>
      <origin xyz="0.00000000 0.00168954 -0.01536935" rpy="0 0 0" />
      <mass value="0.00905901" />
      <inertia ixx="0.00000173" ixy="0.00000000" ixz="0.00000000" iyy="0.00000168" iyz="0.00000025" izz="0.00000025" />
    </inertial>
    <visual>
      <origin xyz="0 0 0" rpy="0 0 0" />
      <geometry>
        <mesh filename="../meshes/L_ring_distal.STL" />
      </geometry>
      <material name="">
        <color rgba="0.752941176470588 0.752941176470588 0.752941176470588 1" />
      </material>
    </visual>
    <collision>
      <origin xyz="0 0 0" rpy="0 0 0" />
      <geometry>
        <mesh filename="../meshes/L_ring_distal.STL" />
      </geometry>
    </collision>
  </link>
  <joint name="L_ring_DIP_joint" type="fixed">
    <origin xyz="0 -0.00111268989759014 -0.0319806491677691" rpy="0 0 0" />
    <parent link="L_ring_proximal" />
    <child link="L_ring_distal" />
    <axis xyz="-1 0 0" />
    <limit lower="0" upper="1.6" effort="1" velocity="1" />
  </joint>
  <link name="L_pinky_proximal">
    <inertial>
      <origin xyz="0.00000000 0.00191043 -0.01322575" rpy="0 0 0" />
      <mass value="0.01313099" />
      <inertia ixx="0.00000194" ixy="0.00000000" ixz="0.00000000" iyy="0.00000194" iyz="0.00000002" izz="0.00000053" />
    </inertial>
    <visual>
      <origin xyz="0 0 0" rpy="0 0 0" />
      <geometry>
        <mesh filename="../meshes/L_pinky_proximal.STL" />
      </geometry>
      <material name="">
        <color rgba="0.752941176470588 0.752941176470588 0.752941176470588 1" />
      </material>
    </visual>
    <collision>
      <origin xyz="0 0 0" rpy="0 0 0" />
      <geometry>
        <mesh filename="../meshes/L_pinky_proximal.STL" />
      </geometry>
    </collision>
  </link>
  <joint name="L_pinky_MCP_joint" type="fixed">
    <origin xyz="-0.0301936481908677 0.00449999999694281 -0.11286583072711" rpy="0 0.12217304772112 0" />
    <parent link="wristRollLeft" />
    <child link="L_pinky_proximal" />
    <axis xyz="-1 0 0" />
    <limit lower="0" upper="1.7" effort="1" velocity="1" />
  </joint>
  <link name="L_pinky_distal">
    <inertial>
      <origin xyz="0.00000199 0.00260409 -0.01099907" rpy="0 0 0" />
      <mass value="0.00693901" />
      <inertia ixx="0.00000086" ixy="0.00000000" ixz="0.00000000" iyy="0.00000084" iyz="0.00000010" izz="0.00000016" />
    </inertial>
    <visual>
      <origin xyz="0 0 0" rpy="0 0 0" />
      <geometry>
        <mesh filename="../meshes/L_pinky_distal.STL" />
      </geometry>
      <material name="">
        <color rgba="0.752941176470588 0.752941176470588 0.752941176470588 1" />
      </material>
    </visual>
    <collision>
      <origin xyz="0 0 0" rpy="0 0 0" />
      <geometry>
        <mesh filename="../meshes/L_pinky_distal.STL" />
      </geometry>
    </collision>
  </link>
  <joint name="L_pinky_DIP_joint" type="fixed">
    <origin xyz="0 -0.00111268989776986 -0.0319806491677628" rpy="0 0 0" />
    <parent link="L_pinky_proximal" />
    <child link="L_pinky_distal" />
    <axis xyz="-1 0 0" />
    <limit lower="0" upper="1.6" effort="1" velocity="1" />
  </joint>
  <link name="shoulderPitchRight">
    <inertial>
      <origin xyz="0.00536737 -0.02693968 0.00010693" rpy="0 0 0" />
      <mass value="0.21648747" />
      <inertia ixx="0.00019065" ixy="-0.00002021" ixz="-0.00000121" iyy="0.00032004" iyz="0.00000016" izz="0.00038133" />
    </inertial>
    <visual>
      <origin xyz="0 0 0" rpy="0 0 0" />
      <geometry>
        <mesh filename="../meshes/shoulderPitchRight.STL" />
      </geometry>
      <material name="">
        <color rgba="1 1 1 1" />
      </material>
    </visual>
    <collision>
      <origin xyz="0 0 0" rpy="0 0 0" />
      <geometry>
        <mesh filename="../meshes/shoulderPitchRight.STL" />
      </geometry>
    </collision>
  </link>
  <joint name="shoulderPitch_Right" type="revolute">
    <origin xyz="0 -0.165093970689321 0.259229560595242" rpy="-0.349065850398898 0 0" />
    <parent link="torso" />
    <child link="shoulderPitchRight" />
    <axis xyz="0 1 0" />
    <limit lower="-3.613" upper="2.042" effort="65" velocity="8" />
  </joint>
  <link name="shoulderRollRight">
    <inertial>
      <origin xyz="-0.03429950 -0.00987424 -0.01571839" rpy="0 0 0" />
      <mass value="1.08875448" />
      <inertia ixx="0.00169651" ixy="0.00000165" ixz="0.00001992" iyy="0.00142236" iyz="0.00044284" izz="0.00093889" />
    </inertial>
    <visual>
      <origin xyz="0 0 0" rpy="0 0 0" />
      <geometry>
        <mesh filename="../meshes/shoulderRollRight.STL" />
      </geometry>
      <material name="">
        <color rgba="0.752941176470588 0.752941176470588 0.752941176470588 1" />
      </material>
    </visual>
    <collision>
      <origin xyz="0 0 0" rpy="0 0 0" />
      <geometry>
        <mesh filename="../meshes/shoulderRollRight.STL" />
      </geometry>
    </collision>
  </link>
  <joint name="shoulderRoll_Right" type="revolute">
    <origin xyz="0.036199999639011 -0.0435000000171988 0" rpy="0.349065850398898 0 0" />
    <parent link="shoulderPitchRight" />
    <child link="shoulderRollRight" />
    <axis xyz="1 0 0" />
    <limit lower="-2.793" upper="0.628" effort="65" velocity="8" />
  </joint>
  <link name="shoulderYawRight">
    <inertial>
      <origin xyz="-0.00051403 0.00046316 -0.06192990" rpy="0 0 0" />
      <mass value="0.90139273" />
      <inertia ixx="0.00328527" ixy="0.00000028" ixz="0.00004741" iyy="0.00317198" iyz="-0.00004934" izz="0.00057584" />
    </inertial>
    <visual>
      <origin xyz="0 0 0" rpy="0 0 0" />
      <geometry>
        <mesh filename="../meshes/shoulderYawRight.STL" />
      </geometry>
      <material name="">
        <color rgba="1 1 1 1" />
      </material>
    </visual>
    <collision>
      <origin xyz="0 0 0" rpy="0 0 0" />
      <geometry>
        <mesh filename="../meshes/shoulderYawRight.STL" />
      </geometry>
    </collision>
  </link>
  <joint name="shoulderYaw_Right" type="revolute">
    <origin xyz="-0.0361999996389017 -0.0339999999996759 -0.0797000000498751" rpy="0 0 0" />
    <parent link="shoulderRollRight" />
    <child link="shoulderYawRight" />
    <axis xyz="0 0 1" />
    <limit lower="-2.583" upper="2.583" effort="65" velocity="8" />
  </joint>
  <link name="elbowRight">
    <inertial>
      <origin xyz="-0.01408915 -0.02929583 -0.02534755" rpy="0 0 0" />
      <mass value="0.91770702" />
      <inertia ixx="0.00096269" ixy="-0.00001024" ixz="0.00026183" iyy="0.00110365" iyz="-0.00002162" izz="0.00059435" />
    </inertial>
    <visual>
      <origin xyz="0 0 0" rpy="0 0 0" />
      <geometry>
        <mesh filename="../meshes/elbowRight.STL" />
      </geometry>
      <material name="">
        <color rgba="0.752941176470588 0.752941176470588 0.752941176470588 1" />
      </material>
    </visual>
    <collision>
      <origin xyz="0 0 0" rpy="0 0 0" />
      <geometry>
        <mesh filename="../meshes/elbowRight.STL" />
      </geometry>
    </collision>
  </link>
  <joint name="elbow_Right" type="revolute">
    <origin xyz="0 0.0284999999998828 -0.182950000001922" rpy="0 0 0" />
    <parent link="shoulderYawRight" />
    <child link="elbowRight" />
    <axis xyz="0 1 0" />
    <limit lower="-2.496" upper="0.209" effort="30" velocity="8" />
  </joint>
  <link name="wristYawRight">
    <inertial>
      <origin xyz="-0.00202981 -0.00013146 -0.09216894" rpy="0 0 0" />
      <mass value="0.95587832" />
      <inertia ixx="0.00256092" ixy="0.00000273" ixz="0.00003067" iyy="0.00250028" iyz="0.00002722" izz="0.00055059" />
    </inertial>
    <visual>
      <origin xyz="0 0 0" rpy="0 0 0" />
      <geometry>
        <mesh filename="../meshes/wristYawRight.STL" />
      </geometry>
      <material name="">
        <color rgba="0.752941176470588 0.752941176470588 0.752941176470588 1" />
      </material>
    </visual>
    <collision>
      <origin xyz="0 0 0" rpy="0 0 0" />
      <geometry>
        <mesh filename="../meshes/wristYawRight.STL" />
      </geometry>
    </collision>
  </link>
  <joint name="wristYaw_Right" type="fixed">
    <origin xyz="-0.0249999999999065 -0.0285000000002922 -0.0728999999999894" rpy="0 0 0" />
    <parent link="elbowRight" />
    <child link="wristYawRight" />
    <axis xyz="0 0 1" />
    <limit lower="-2.67" upper="2.67" effort="6.4" velocity="5" />
  </joint>
  <link name="wristPitchRight">
    <inertial>
      <origin xyz="-0.00017580 0.00166098 -0.00002773" rpy="0 0 0" />
      <mass value="0.11963454" />
      <inertia ixx="0.00003359" ixy="0.00000002" ixz="0.00000000" iyy="0.00002690" iyz="-0.00000005" izz="0.00003977" />
    </inertial>
    <visual>
      <origin xyz="0 0 0" rpy="0 0 0" />
      <geometry>
        <mesh filename="../meshes/wristPitchRight.STL" />
      </geometry>
      <material name="">
        <color rgba="1 1 1 1" />
      </material>
    </visual>
    <collision>
      <origin xyz="0 0 0" rpy="0 0 0" />
      <geometry>
        <mesh filename="../meshes/wristPitchRight.STL" />
      </geometry>
    </collision>
  </link>
  <joint name="wristPitch_Right" type="fixed">
    <origin xyz="0 0 -0.201699999999861" rpy="0 0 0" />
    <parent link="wristYawRight" />
    <child link="wristPitchRight" />
    <axis xyz="0 1 0" />
    <limit lower="-0.96" upper="0.96" effort="6.4" velocity="5" />
  </joint>
  <link name="wristRollRight">
    <inertial>
      <origin xyz="-0.00030616 -0.00861825 -0.06634429" rpy="0 0 0" />
      <mass value="0.35815530" />
      <inertia ixx="0.00032078" ixy="-0.00001180" ixz="-0.00000453" iyy="0.00043005" iyz="0.00002137" izz="0.00018497" />
    </inertial>
    <visual>
      <origin xyz="0 0 0" rpy="0 0 0" />
      <geometry>
        <mesh filename="../meshes/wristRollRight.STL" />
      </geometry>
      <material name="">
        <color rgba="0.752941176470588 0.752941176470588 0.752941176470588 1" />
      </material>
    </visual>
    <collision>
      <origin xyz="0 0 0" rpy="0 0 0" />
      <geometry>
        <mesh filename="../meshes/wristRollRight.STL" />
      </geometry>
    </collision>
  </link>
  <joint name="wristRoll_Right" type="fixed">
    <origin xyz="0 0 0" rpy="0 0 0" />
    <parent link="wristPitchRight" />
    <child link="wristRollRight" />
    <axis xyz="1 0 0" />
    <limit lower="-0.96" upper="0.96" effort="6.4" velocity="5" />
  </joint>
  <link name="R_thumb_proximal_base">
    <inertial>
      <origin xyz="0.00431634 -0.00026726 -0.00141884" rpy="0 0 0" />
      <mass value="0.00893190" />
      <inertia ixx="0.00000031" ixy="0.00000008" ixz="-0.00000006" iyy="0.00000055" iyz="-0.00000001" izz="0.00000046" />
    </inertial>
    <visual>
      <origin xyz="0 0 0" rpy="0 0 0" />
      <geometry>
        <mesh filename="../meshes/R_thumb_proximal_base.STL" />
      </geometry>
      <material name="">
        <color rgba="0.752941176470588 0.752941176470588 0.752941176470588 1" />
      </material>
    </visual>
    <collision>
      <origin xyz="0 0 0" rpy="0 0 0" />
      <geometry>
        <mesh filename="../meshes/R_thumb_proximal_base.STL" />
      </geometry>
    </collision>
  </link>
  <joint name="R_thumb_MCP_joint1" type="fixed">
    <origin xyz="0.0244999999998152 0.0100000000000263 -0.0470000000000906" rpy="0 0 0" />
    <parent link="wristRollRight" />
    <child link="R_thumb_proximal_base" />
    <axis xyz="0 0 1" />
    <limit lower="0" upper="1.1" effort="1" velocity="1" />
  </joint>
  <link name="R_thumb_proximal">
    <inertial>
      <origin xyz="0.02369685 0.00000000 -0.01467226" rpy="0 0 0" />
      <mass value="0.06158426" />
      <inertia ixx="0.00001171" ixy="0.00000000" ixz="-0.00000575" iyy="0.00002013" iyz="0.00000000" izz="0.00001139" />
    </inertial>
    <visual>
      <origin xyz="0 0 0" rpy="0 0 0" />
      <geometry>
        <mesh filename="../meshes/R_thumb_proximal.STL" />
      </geometry>
      <material name="">
        <color rgba="0.752941176470588 0.752941176470588 0.752941176470588 1" />
      </material>
    </visual>
    <collision>
      <origin xyz="0 0 0" rpy="0 0 0" />
      <geometry>
        <mesh filename="../meshes/R_thumb_proximal.STL" />
      </geometry>
    </collision>
  </link>
  <joint name="R_thumb_MCP_joint2" type="fixed">
    <origin xyz="0.0119540024564323 0.00104967865159283 0" rpy="0 0 0.0875851579817108" />
    <parent link="R_thumb_proximal_base" />
    <child link="R_thumb_proximal" />
    <axis xyz="0 1 0" />
    <limit lower="0" upper="0.5" effort="1" velocity="1" />
  </joint>
  <link name="R_thumb_intermediate">
    <inertial>
      <origin xyz="0.00973134 0.00000000 -0.00266467" rpy="0 0 0" />
      <mass value="0.01538338" />
      <inertia ixx="0.00000142" ixy="0.00000000" ixz="-0.00000039" iyy="0.00000172" iyz="0.00000000" izz="0.00000100" />
    </inertial>
    <visual>
      <origin xyz="0 0 0" rpy="0 0 0" />
      <geometry>
        <mesh filename="../meshes/R_thumb_intermediate.STL" />
      </geometry>
      <material name="">
        <color rgba="0.752941176470588 0.752941176470588 0.752941176470588 1" />
      </material>
    </visual>
    <collision>
      <origin xyz="0 0 0" rpy="0 0 0" />
      <geometry>
        <mesh filename="../meshes/R_thumb_intermediate.STL" />
      </geometry>
    </collision>
  </link>
  <joint name="R_thumb_PIP_joint" type="fixed">
    <origin xyz="0.044288564116179 0 -0.0376632856841606" rpy="0 0 0" />
    <parent link="R_thumb_proximal" />
    <child link="R_thumb_intermediate" />
    <axis xyz="0 1 0" />
    <limit lower="0" upper="1" effort="1" velocity="1" />
  </joint>
  <link name="R_thumb_distal">
    <inertial>
      <origin xyz="0.00714151 0.00000139 -0.00689413" rpy="0 0 0" />
      <mass value="0.01043741" />
      <inertia ixx="0.00000076" ixy="0.00000000" ixz="-0.00000020" iyy="0.00000086" iyz="0.00000000" izz="0.00000052" />
    </inertial>
    <visual>
      <origin xyz="0 0 0" rpy="0 0 0" />
      <geometry>
        <mesh filename="../meshes/R_thumb_distal.STL" />
      </geometry>
      <material name="">
        <color rgba="0.752941176470588 0.752941176470588 0.752941176470588 1" />
      </material>
    </visual>
    <collision>
      <origin xyz="0 0 0" rpy="0 0 0" />
      <geometry>
        <mesh filename="../meshes/R_thumb_distal.STL" />
      </geometry>
    </collision>
  </link>
  <joint name="R_thumb_DIP_joint" type="fixed">
    <origin xyz="0.0164679343353944 0 -0.0154614727217485" rpy="0 0 0" />
    <parent link="R_thumb_intermediate" />
    <child link="R_thumb_distal" />
    <axis xyz="0 1 0" />
    <limit lower="0" upper="1.2" effort="1" velocity="1" />
  </joint>
  <link name="R_index_proximal">
    <inertial>
      <origin xyz="0.00000000 -0.00199820 -0.01311710" rpy="0 0 0" />
      <mass value="0.01454119" />
      <inertia ixx="0.00000195" ixy="0.00000000" ixz="0.00000000" iyy="0.00000195" iyz="-0.00000002" izz="0.00000054" />
    </inertial>
    <visual>
      <origin xyz="0 0 0" rpy="0 0 0" />
      <geometry>
        <mesh filename="../meshes/R_index_proximal.STL" />
      </geometry>
      <material name="">
        <color rgba="0.752941176470588 0.752941176470588 0.752941176470588 1" />
      </material>
    </visual>
    <collision>
      <origin xyz="0 0 0" rpy="0 0 0" />
      <geometry>
        <mesh filename="../meshes/R_index_proximal.STL" />
      </geometry>
    </collision>
  </link>
  <joint name="R_index_MCP_joint" type="fixed">
    <origin xyz="0.0269420472120735 -0.00950000000009146 -0.114975331625641" rpy="0 -0.0523598775568891 0" />
    <parent link="wristRollRight" />
    <child link="R_index_proximal" />
    <axis xyz="1 0 0" />
    <limit lower="0" upper="1.7" effort="1" velocity="1" />
  </joint>
  <link name="R_index_distal">
    <inertial>
      <origin xyz="0.00000000 -0.00168936 -0.01536965" rpy="0 0 0" />
      <mass value="0.00905901" />
      <inertia ixx="0.00000173" ixy="0.00000000" ixz="0.00000000" iyy="0.00000168" iyz="-0.00000025" izz="0.00000025" />
    </inertial>
    <visual>
      <origin xyz="0 0 0" rpy="0 0 0" />
      <geometry>
        <mesh filename="../meshes/R_index_distal.STL" />
      </geometry>
      <material name="">
        <color rgba="0.752941176470588 0.752941176470588 0.752941176470588 1" />
      </material>
    </visual>
    <collision>
      <origin xyz="0 0 0" rpy="0 0 0" />
      <geometry>
        <mesh filename="../meshes/R_index_distal.STL" />
      </geometry>
    </collision>
  </link>
  <joint name="R_index_DIP_joint" type="fixed">
    <origin xyz="0 0.00111268989722751 -0.0319806491677816" rpy="0 0 0" />
    <parent link="R_index_proximal" />
    <child link="R_index_distal" />
    <axis xyz="1 0 0" />
    <limit lower="0" upper="1.6" effort="1" velocity="1" />
  </joint>
  <link name="R_middle_proximal">
    <inertial>
      <origin xyz="0.00000000 -0.00115549 -0.01334194" rpy="0 0 0" />
      <mass value="0.01313107" />
      <inertia ixx="0.00000194" ixy="0.00000000" ixz="0.00000000" iyy="0.00000193" iyz="-0.00000010" izz="0.00000054" />
    </inertial>
    <visual>
      <origin xyz="0 0 0" rpy="0 0 0" />
      <geometry>
        <mesh filename="../meshes/R_middle_proximal.STL" />
      </geometry>
      <material name="">
        <color rgba="0.752941176470588 0.752941176470588 0.752941176470588 1" />
      </material>
    </visual>
    <collision>
      <origin xyz="0 0 0" rpy="0 0 0" />
      <geometry>
        <mesh filename="../meshes/R_middle_proximal.STL" />
      </geometry>
    </collision>
  </link>
  <joint name="R_middle_MCP_joint" type="fixed">
    <origin xyz="0.00799999999968861 -0.0145000000002054 -0.127999999999992" rpy="0 0 0" />
    <parent link="wristRollRight" />
    <child link="R_middle_proximal" />
    <axis xyz="1 0 0" />
    <limit lower="0" upper="1.7" effort="1" velocity="1" />
  </joint>
  <link name="R_middle_distal">
    <inertial>
      <origin xyz="0.00000000 0.00003955 -0.01546217" rpy="0 0 0" />
      <mass value="0.00905901" />
      <inertia ixx="0.00000173" ixy="0.00000000" ixz="0.00000000" iyy="0.00000161" iyz="-0.00000040" izz="0.00000032" />
    </inertial>
    <visual>
      <origin xyz="0 0 0" rpy="0 0 0" />
      <geometry>
        <mesh filename="../meshes/R_middle_distal.STL" />
      </geometry>
      <material name="">
        <color rgba="0.752941176470588 0.752941176470588 0.752941176470588 1" />
      </material>
    </visual>
    <collision>
      <origin xyz="0 0 0" rpy="0 0 0" />
      <geometry>
        <mesh filename="../meshes/R_middle_distal.STL" />
      </geometry>
    </collision>
  </link>
  <joint name="R_middle_DIP_joint" type="fixed">
    <origin xyz="0 0.00293735370559906 -0.0318649015879289" rpy="0 0 0" />
    <parent link="R_middle_proximal" />
    <child link="R_middle_distal" />
    <axis xyz="1 0 0" />
    <limit lower="0" upper="1.6" effort="1" velocity="1" />
  </joint>
  <link name="R_ring_proximal">
    <inertial>
      <origin xyz="0.00000000 -0.00199820 -0.01311710" rpy="0 0 0" />
      <mass value="0.01454119" />
      <inertia ixx="0.00000195" ixy="0.00000000" ixz="0.00000000" iyy="0.00000195" iyz="-0.00000002" izz="0.00000054" />
    </inertial>
    <visual>
      <origin xyz="0 0 0" rpy="0 0 0" />
      <geometry>
        <mesh filename="../meshes/R_ring_proximal.STL" />
      </geometry>
      <material name="">
        <color rgba="0.752941176470588 0.752941176470588 0.752941176470588 1" />
      </material>
    </visual>
    <collision>
      <origin xyz="0 0 0" rpy="0 0 0" />
      <geometry>
        <mesh filename="../meshes/R_ring_proximal.STL" />
      </geometry>
    </collision>
  </link>
  <joint name="R_ring_MCP_joint" type="fixed">
    <origin xyz="-0.0109420472126836 -0.00950000000027432 -0.119975331625507" rpy="0 0.0523598775627611 0" />
    <parent link="wristRollRight" />
    <child link="R_ring_proximal" />
    <axis xyz="1 0 0" />
    <limit lower="0" upper="1.7" effort="1" velocity="1" />
  </joint>
  <link name="R_ring_distal">
    <inertial>
      <origin xyz="0.00000000 -0.00168936 -0.01536965" rpy="0 0 0" />
      <mass value="0.00905901" />
      <inertia ixx="0.00000173" ixy="0.00000000" ixz="0.00000000" iyy="0.00000168" iyz="-0.00000025" izz="0.00000025" />
    </inertial>
    <visual>
      <origin xyz="0 0 0" rpy="0 0 0" />
      <geometry>
        <mesh filename="../meshes/R_ring_distal.STL" />
      </geometry>
      <material name="">
        <color rgba="0.752941176470588 0.752941176470588 0.752941176470588 1" />
      </material>
    </visual>
    <collision>
      <origin xyz="0 0 0" rpy="0 0 0" />
      <geometry>
        <mesh filename="../meshes/R_ring_distal.STL" />
      </geometry>
    </collision>
  </link>
  <joint name="R_ring_DIP_joint" type="fixed">
    <origin xyz="0 0.00111268989721214 -0.0319806491677822" rpy="0 0 0" />
    <parent link="R_ring_proximal" />
    <child link="R_ring_distal" />
    <axis xyz="1 0 0" />
    <limit lower="0" upper="1.6" effort="1" velocity="1" />
  </joint>
  <link name="R_pinky_proximal">
    <inertial>
      <origin xyz="0.00000000 -0.00191046 -0.01322577" rpy="0 0 0" />
      <mass value="0.01313107" />
      <inertia ixx="0.00000194" ixy="0.00000000" ixz="0.00000000" iyy="0.00000194" iyz="-0.00000002" izz="0.00000053" />
    </inertial>
    <visual>
      <origin xyz="0 0 0" rpy="0 0 0" />
      <geometry>
        <mesh filename="../meshes/R_pinky_proximal.STL" />
      </geometry>
      <material name="">
        <color rgba="0.752941176470588 0.752941176470588 0.752941176470588 1" />
      </material>
    </visual>
    <collision>
      <origin xyz="0 0 0" rpy="0 0 0" />
      <geometry>
        <mesh filename="../meshes/R_pinky_proximal.STL" />
      </geometry>
    </collision>
  </link>
  <joint name="R_pinky_MCP_joint" type="fixed">
    <origin xyz="-0.0301936481816091 -0.00450000000035261 -0.112865830729451" rpy="0 0.122173047642494 0" />
    <parent link="wristRollRight" />
    <child link="R_pinky_proximal" />
    <axis xyz="1 0 0" />
    <limit lower="0" upper="1.7" effort="1" velocity="1" />
  </joint>
  <link name="R_pinky_distal">
    <inertial>
      <origin xyz="0.00000201 -0.00260417 -0.01099890" rpy="0 0 0" />
      <mass value="0.00693901" />
      <inertia ixx="0.00000086" ixy="0.00000000" ixz="0.00000000" iyy="0.00000084" iyz="-0.00000010" izz="0.00000016" />
    </inertial>
    <visual>
      <origin xyz="0 0 0" rpy="0 0 0" />
      <geometry>
        <mesh filename="../meshes/R_pinky_distal.STL" />
      </geometry>
      <material name="">
        <color rgba="0.752941176470588 0.752941176470588 0.752941176470588 1" />
      </material>
    </visual>
    <collision>
      <origin xyz="0 0 0" rpy="0 0 0" />
      <geometry>
        <mesh filename="../meshes/R_pinky_distal.STL" />
      </geometry>
    </collision>
  </link>
  <joint name="R_pinky_DIP_joint" type="fixed">
    <origin xyz="0 0.00111268989720342 -0.0319806491677825" rpy="0 0 0" />
    <parent link="R_pinky_proximal" />
    <child link="R_pinky_distal" />
    <axis xyz="1 0 0" />
    <limit lower="0" upper="1.6" effort="1" velocity="1" />
  </joint>
</robot>
