<?xml version='1.0' encoding='utf-8'?>
<mujoco model="adam_sp">
  <compiler angle="radian" meshdir="meshes_stl_0.25/" />

  <default>
    <!-- <joint frictionloss="1"/> -->
    <joint damping="0.001" armature="0.01" frictionloss="0.1"/>
    <!-- 刚性地板 -->
    <geom solimp="0.95 0.95 0.001" solref="0.005 1"/> 
    
  </default>
  <asset>
    <mesh name="pelvis" file="pelvis.STL" />
    <mesh name="hipPitchLeft" file="hipPitchLeft.STL" />
    <mesh name="hipRollLeft" file="hipRollLeft.STL" />
    <mesh name="thighLeft" file="thighLeft.STL" />
    <mesh name="shinLeft" file="shinLeft.STL" />
    <mesh name="anklePitchLeft" file="anklePitchLeft.STL" />
    <mesh name="toeLeft" file="toeLeft.STL" />
    <mesh name="hipPitchRight" file="hipPitchRight.STL" />
    <mesh name="hipRollRight" file="hipRollRight.STL" />
    <mesh name="thighRight" file="thighRight.STL" />
    <mesh name="shinRight" file="shinRight.STL" />
    <mesh name="anklePitchRight" file="anklePitchRight.STL" />
    <mesh name="toeRight" file="toeRight.STL" />
    <mesh name="waistRoll" file="waistRoll.STL" />
    <mesh name="waistPitch" file="waistPitch.STL" />
    <mesh name="torso" file="torso.STL" />
    <mesh name="shoulderPitchLeft" file="shoulderPitchLeft.STL" />
    <mesh name="shoulderRollLeft" file="shoulderRollLeft.STL" />
    <mesh name="shoulderYawLeft" file="shoulderYawLeft.STL" />
    <mesh name="elbowLeft" file="elbowLeft.STL" />
    <mesh name="wristYawLeft" file="wristYawLeft.STL" />
    <mesh name="wristPitchLeft" file="wristPitchLeft.STL" />
    <mesh name="wristRollLeft" file="wristRollLeft.STL" />
    <mesh name="L_thumb_proximal_base" file="L_thumb_proximal_base.STL" />
    <mesh name="L_thumb_proximal" file="L_thumb_proximal.STL" />
    <mesh name="L_thumb_intermediate" file="L_thumb_intermediate.STL" />
    <mesh name="L_thumb_distal" file="L_thumb_distal.STL" />
    <mesh name="L_index_proximal" file="L_index_proximal.STL" />
    <mesh name="L_index_distal" file="L_index_distal.STL" />
    <mesh name="L_middle_proximal" file="L_middle_proximal.STL" />
    <mesh name="L_middle_distal" file="L_middle_distal.STL" />
    <mesh name="L_ring_proximal" file="L_ring_proximal.STL" />
    <mesh name="L_ring_distal" file="L_ring_distal.STL" />
    <mesh name="L_pinky_proximal" file="L_pinky_proximal.STL" />
    <mesh name="L_pinky_distal" file="L_pinky_distal.STL" />
    <mesh name="shoulderPitchRight" file="shoulderPitchRight.STL" />
    <mesh name="shoulderRollRight" file="shoulderRollRight.STL" />
    <mesh name="shoulderYawRight" file="shoulderYawRight.STL" />
    <mesh name="elbowRight" file="elbowRight.STL" />
    <mesh name="wristYawRight" file="wristYawRight.STL" />
    <mesh name="wristPitchRight" file="wristPitchRight.STL" />
    <mesh name="wristRollRight" file="wristRollRight.STL" />
    <mesh name="R_thumb_proximal_base" file="R_thumb_proximal_base.STL" />
    <mesh name="R_thumb_proximal" file="R_thumb_proximal.STL" />
    <mesh name="R_thumb_intermediate" file="R_thumb_intermediate.STL" />
    <mesh name="R_thumb_distal" file="R_thumb_distal.STL" />
    <mesh name="R_index_proximal" file="R_index_proximal.STL" />
    <mesh name="R_index_distal" file="R_index_distal.STL" />
    <mesh name="R_middle_proximal" file="R_middle_proximal.STL" />
    <mesh name="R_middle_distal" file="R_middle_distal.STL" />
    <mesh name="R_ring_proximal" file="R_ring_proximal.STL" />
    <mesh name="R_ring_distal" file="R_ring_distal.STL" />
    <mesh name="R_pinky_proximal" file="R_pinky_proximal.STL" />
    <mesh name="R_pinky_distal" file="R_pinky_distal.STL" />
  </asset>
  <worldbody>
    <body name="pelvis" pos="0 0 0.95">
      <inertial pos="-0.000347206 0 -0.00735688" quat="0.497146 0.497124 -0.502857 0.502841" mass="10.3575" diaginertia="0.0688803 0.0622175 0.0346152" />
      <joint name="floating_base" type="free" limited="false" actuatorfrclimited="false" />
      <geom type="mesh" contype="0" conaffinity="0" group="1" density="0" rgba="0.752941 0.752941 0.752941 1" mesh="pelvis" />
      <geom size="0.08 0.08" quat="0.707388 0.706825 0 0" type="cylinder" />
      <!-- <geom type="mesh" rgba="0.752941 0.752941 0.752941 1" mesh="pelvis" /> -->
      <body name="hipPitchLeft" pos="0 0.0961925 -0.0332412" quat="0.953717 -0.300706 0 0">
        <inertial pos="-0.0566022 0.0576144 -0.00077159" quat="0.0368179 0.561016 0.441278 0.699414" mass="2.2338" diaginertia="0.00517658 0.00512865 0.00286301" />
        <joint name="hipPitch_Left" pos="0 0 0" axis="0 1 0" range="-2.164 2.164" actuatorfrcrange="-230 230" />
        <geom type="mesh" contype="0" conaffinity="0" group="1" density="0" rgba="0.752941 0.752941 0.752941 1" mesh="hipPitchLeft" />
        <!-- <geom type="mesh" rgba="0.752941 0.752941 0.752941 1" mesh="hipPitchLeft" /> -->
        <body name="hipRollLeft" pos="-0.0255 0.069 0" quat="0.953717 0.300706 0 0">
          <inertial pos="0.0392416 4.107e-05 -0.0103292" quat="-0.0395792 0.570417 0.0171079 0.820223" mass="1.35108" diaginertia="0.00141415 0.00129142 0.00119555" />
          <joint name="hipRoll_Left" pos="0 0 0" axis="1 0 0" range="-0.733 1.605" actuatorfrcrange="-160 160" />
          <geom type="mesh" contype="0" conaffinity="0" group="1" density="0" rgba="0.752941 0.752941 0.752941 1" mesh="hipRollLeft" />
          <geom size="0.04 0.08" pos="0 0 0" quat="0.707105 0 0.707108 0" type="cylinder" />
          <!-- <geom type="mesh" rgba="0.752941 0.752941 0.752941 1" mesh="hipRollLeft" /> -->
          <body name="thighLeft" pos="0.044 0 -0.0525">
            <inertial pos="0.00244052 -0.00866423 -0.134336" quat="0.680512 0.0474927 -0.0296876 0.730593" mass="6.43433" diaginertia="0.0639674 0.0582829 0.0126725" />
            <joint name="hipYaw_Left" pos="0 0 0" axis="0 0 1" range="-0.785 0.785" actuatorfrcrange="-105 105" />
            <geom type="mesh" contype="0" conaffinity="0" group="1" density="0" rgba="0.752941 0.752941 0.752941 1" mesh="thighLeft" />
            <geom size="0.05 0.04 0.12" pos="0 0 -0.2" type="box" />
            <!-- <geom type="mesh" rgba="0.752941 0.752941 0.752941 1" mesh="thighLeft" /> -->
            <body name="shinLeft" pos="0 -0.0355 -0.369">
              <inertial pos="-0.00053135 0.00081959 -0.145381" quat="0.621823 -0.00559949 -0.00582195 0.783116" mass="2.25363" diaginertia="0.0215915 0.0215147 0.00136466" />
              <joint name="kneePitch_Left" pos="0 0 0" axis="0 1 0" range="0.052 2.391" actuatorfrcrange="-230 230" />
              <geom type="mesh" contype="0" conaffinity="0" group="1" density="0" rgba="0.752941 0.752941 0.752941 1" mesh="shinLeft" />
              <geom size="0.04 0.03 0.15" pos="0 0 -0.2" type="box" />
              <!-- <geom type="mesh" rgba="0.752941 0.752941 0.752941 1" mesh="shinLeft" /> -->
              <body name="anklePitchLeft" pos="0 0 -0.37">
                <inertial pos="0 0 0" mass="0.0301423" diaginertia="3.14e-06 3.14e-06 2.04e-06" />
                <joint name="anklePitch_Left" pos="0 0 0" axis="0 1 0" range="-1 0.35" actuatorfrcrange="-40 40" />
                <geom type="mesh" contype="0" conaffinity="0" group="1" density="0" rgba="1 1 1 1" mesh="anklePitchLeft" />
                <!-- <geom type="mesh" rgba="1 1 1 1" mesh="anklePitchLeft" /> -->
                <body name="toeLeft">
                  <inertial pos="0.0374997 -4.016e-05 -0.0419674" quat="0.00341207 0.66841 -0.00284521 0.74378" mass="0.634796" diaginertia="0.0023347 0.00226908 0.000434692" />
                  <joint name="ankleRoll_Left" pos="0 0 0" axis="1 0 0" range="-0.3491 0.3491" actuatorfrcrange="-12 12" />
                  <geom type="mesh" contype="0" conaffinity="0" group="1" density="0" rgba="0.752941 0.752941 0.752941 1" mesh="toeLeft" />
                  <!-- <geom type="mesh" rgba="0.752941 0.752941 0.752941 1" mesh="toeLeft" /> -->
                  <!-- <geom name="toe_left" size="0.12 0.05 0.015" pos="0.047 0.0 -0.05" quat="0 0 0 1" type="box" rgba="1 0 0 0" /> -->
                  <!-- <geom name="toe_left" type="mesh" mesh="toeLeft" /> -->
                  <geom name="toe1_left" size="0.015 0.11" pos="0.045 0.025 -0.049" quat="0.703845 0 0.710353 0"
                    type="cylinder" />
                  <geom name="toe2_left" size="0.015 0.11" pos="0.045 -0.025 -0.049" quat="0.703845 0 0.710353 0"
                    type="cylinder" />
                </body>
              </body>
            </body>
          </body>
        </body>
      </body>
      <body name="hipPitchRight" pos="0 -0.0961925 -0.0332412" quat="0.953717 0.300706 0 0">
        <inertial pos="-0.0566179 -0.0575934 -0.00078211" quat="-0.0285368 0.566536 -0.434359 0.699682" mass="2.23477" diaginertia="0.00517891 0.00513008 0.00286639" />
        <joint name="hipPitch_Right" pos="0 0 0" axis="0 1 0" range="-2.164 2.164" actuatorfrcrange="-230 230" />
        <geom type="mesh" contype="0" conaffinity="0" group="1" density="0" rgba="0.752941 0.752941 0.752941 1" mesh="hipPitchRight" />
        <!-- <geom type="mesh" rgba="0.752941 0.752941 0.752941 1" mesh="hipPitchRight" /> -->
        <body name="hipRollRight" pos="-0.0255 -0.069 0" quat="0.953717 -0.300706 0 0">
          <inertial pos="0.0392598 -5.814e-05 -0.0103241" quat="0.0423906 0.568479 -0.0183416 0.8214" mass="1.3517" diaginertia="0.00141624 0.00129238 0.00119482" />
          <joint name="hipRoll_Right" pos="0 0 0" axis="1 0 0" range="-1.605 0.733" actuatorfrcrange="-160 160" />
          <geom type="mesh" contype="0" conaffinity="0" group="1" density="0" rgba="0.752941 0.752941 0.752941 1" mesh="hipRollRight" />
          <!-- <geom type="mesh" rgba="0.752941 0.752941 0.752941 1" mesh="hipRollRight" /> -->
          <geom size="0.04 0.08" pos="0 0 0" quat="0.707105 0 0.707108 0" type="cylinder" />
          <body name="thighRight" pos="0.044 0 -0.0525">
            <inertial pos="0.00245598 0.00865064 -0.134332" quat="0.730252 -0.0298313 0.0474381 0.680876" mass="6.43084" diaginertia="0.0639418 0.0582427 0.0126798" />
            <joint name="hipYaw_Right" pos="0 0 0" axis="0 0 1" range="-0.785 0.785" actuatorfrcrange="-105 105" />
            <geom type="mesh" contype="0" conaffinity="0" group="1" density="0" rgba="0.752941 0.752941 0.752941 1" mesh="thighRight" />
            <!-- <geom type="mesh" rgba="0.752941 0.752941 0.752941 1" mesh="thighRight" /> -->
            <geom size="0.05 0.04 0.12" pos="0 0 -0.2" type="box" />
            <body name="shinRight" pos="0 0.0355 -0.369">
              <inertial pos="-0.00052844 -0.00082152 -0.145334" quat="0.77964 -0.00587298 -0.00552291 0.626176" mass="2.25459" diaginertia="0.0215714 0.0214966 0.00136482" />
              <joint name="kneePitch_Right" pos="0 0 0" axis="0 1 0" range="0.052 2.391" actuatorfrcrange="-230 230" />
              <geom type="mesh" contype="0" conaffinity="0" group="1" density="0" rgba="0.752941 0.752941 0.752941 1" mesh="shinRight" />
              <geom size="0.04 0.03 0.15" pos="0 0 -0.2" type="box" />
              <!-- <geom type="mesh" rgba="0.752941 0.752941 0.752941 1" mesh="shinRight" /> -->
              <body name="anklePitchRight" pos="0 0 -0.37">
                <inertial pos="0 0 0" mass="0.0301423" diaginertia="3.14e-06 3.14e-06 2.04e-06" />
                <joint name="anklePitch_Right" pos="0 0 0" axis="0 1 0" range="-1 0.35" actuatorfrcrange="-40 40" />
                <geom type="mesh" contype="0" conaffinity="0" group="1" density="0" rgba="1 1 1 1" mesh="anklePitchRight" />
                <!-- <geom type="mesh" rgba="1 1 1 1" mesh="anklePitchRight" /> -->
                <body name="toeRight">
                  <inertial pos="0.0375023 4.002e-05 -0.0419671" quat="-0.00346801 0.668408 0.00279542 0.743782" mass="0.634808" diaginertia="0.0023347 0.00226908 0.00043472" />
                  <joint name="ankleRoll_Right" pos="0 0 0" axis="1 0 0" range="-0.3491 0.3491" actuatorfrcrange="-12 12" />
                  <geom type="mesh" contype="0" conaffinity="0" group="1" density="0" rgba="0.752941 0.752941 0.752941 1" mesh="toeRight" />
                  <!-- <geom type="mesh" rgba="0.752941 0.752941 0.752941 1" mesh="toeRight" /> -->
                  <!-- <geom name="toe_right" size="0.12 0.05 0.015" pos="0.047 0.0 -0.05" quat="0 0 0 1" type="box" rgba="1 0 0 0" /> -->
                  <!-- <geom name="toe_right" type="mesh" mesh="toeRight" /> -->
                  <geom name="toe1_right" size="0.015 0.11" pos="0.045 0.025 -0.049" quat="0.703845 0 0.710353 0"
                    type="cylinder" />
                  <geom name="toe2_right" size="0.015 0.11" pos="0.045 -0.025 -0.049" quat="0.703845 0 0.710353 0"
                    type="cylinder" />
                </body>
              </body>
            </body>
          </body>
        </body>
      </body>
      <body name="waistRoll_link" pos="0 0 0.044">
        <inertial pos="0.00093826 0.00093832 0.0399999" quat="0.383833 0.0123801 -0.00511148 0.923305" mass="2.36268" diaginertia="0.00543471 0.00542871 0.00184736" />
        <joint name="waistRoll" pos="0 0 0" axis="1 0 0" range="-0.279 0.279" actuatorfrcrange="-110 110" />
        <geom type="mesh" contype="0" conaffinity="0" group="1" density="0" rgba="1 1 1 1" mesh="waistRoll" />
        <!-- <geom type="mesh" rgba="1 1 1 1" mesh="waistRoll" /> -->
        <body name="waistPitch_link" pos="0 0 0.08">
          <inertial pos="-8.401e-05 0.00189362 0.0254832" quat="0.516813 0.52977 -0.475496 0.475554" mass="0.563538" diaginertia="0.00155964 0.00151442 0.000672501" />
          <joint name="waistPitch" pos="0 0 0" axis="0 1 0" range="-0.663 1.361" actuatorfrcrange="-110 110" />
          <geom type="mesh" contype="0" conaffinity="0" group="1" density="0" rgba="0.752941 0.752941 0.752941 1" mesh="waistPitch" />
          <!-- <geom type="mesh" rgba="0.752941 0.752941 0.752941 1" mesh="waistPitch" /> -->
          <body name="torso" pos="0 0.0005 0.053">
            <inertial pos="-3.545e-05 0.00048442 0.185924" quat="0.999918 -0.00116744 -0.012015 -0.00434505" mass="13.4634" diaginertia="0.211446 0.168649 0.0770068" />
            <joint name="waistYaw" pos="0 0 0" axis="0 0 1" range="-0.829 0.829" actuatorfrcrange="-110 110" />
            <geom type="mesh" contype="0" conaffinity="0" group="1" density="0" rgba="0.752941 0.752941 0.752941 1" mesh="torso" />
            <geom size="0.13" pos="0 0 0.15" />
            <!-- <geom type="mesh" rgba="0.752941 0.752941 0.752941 1" mesh="torso" /> -->
            <body name="shoulderPitchLeft" pos="0 0.165094 0.25923" quat="0.984808 0.173648 0 0">
              <inertial pos="0.00542694 0.0268987 0.00010792" quat="0.0525836 0.7027 -0.0564441 0.707292" mass="0.216148" diaginertia="0.000380649 0.000322752 0.000187229" />
              <joint name="shoulderPitch_Left" pos="0 0 0" axis="0 1 0" range="-3.613 2.042" actuatorfrcrange="-65 65" />
              <geom type="mesh" contype="0" conaffinity="0" group="1" density="0" rgba="1 1 1 1" mesh="shoulderPitchLeft" />
              <geom size="0.035 0.04" pos="0 0 0" quat="0.707105 0 0.707108 0" type="cylinder" />
              <!-- <geom type="mesh" rgba="1 1 1 1" mesh="shoulderPitchLeft" /> -->
              <body name="shoulderRollLeft" pos="0.0362 0.0435 0" quat="0.984808 -0.173648 0 0">
                <inertial pos="-0.0343733 0.00962154 -0.0154456" quat="0.915483 -0.248083 -0.0900009 -0.303719" mass="1.07882" diaginertia="0.0016821 0.0016513 0.000668275" />
                <joint name="shoulderRoll_Left" pos="0 0 0" axis="1 0 0" range="-0.628 2.793" actuatorfrcrange="-65 65" />
                <geom type="mesh" contype="0" conaffinity="0" group="1" density="0" rgba="0.752941 0.752941 0.752941 1" mesh="shoulderRollLeft" />
                <!-- <geom type="mesh" rgba="0.752941 0.752941 0.752941 1" mesh="shoulderRollLeft" /> -->
                <body name="shoulderYawLeft" pos="-0.0362 0.034 -0.0797">
                  <inertial pos="-0.00051421 -0.00044442 -0.0619328" quat="0.999905 0.00947141 -0.00878878 0.00478573" mass="0.90142" diaginertia="0.00328642 0.00317319 0.000574119" />
                  <joint name="shoulderYaw_Left" pos="0 0 0" axis="0 0 1" range="-2.583 2.583" actuatorfrcrange="-65 65" />
                  <geom type="mesh" contype="0" conaffinity="0" group="1" density="0" rgba="1 1 1 1" mesh="shoulderYawLeft" />
                  <geom size="0.03 0.075" pos="0 0 -0.08" type="cylinder" />
                  <!-- <geom type="mesh" rgba="1 1 1 1" mesh="shoulderYawLeft" /> -->
                  <body name="elbowLeft" pos="0 -0.0285 -0.18295">
                    <inertial pos="-0.0140727 0.0292971 -0.0253473" quat="0.882767 -0.0885577 -0.220164 0.405471" mass="0.917707" diaginertia="0.0011212 0.00108213 0.000458232" />
                    <joint name="elbow_Left" pos="0 0 0" axis="0 1 0" range="-2.496 0.209" actuatorfrcrange="-30 30" />
                    <geom type="mesh" contype="0" conaffinity="0" group="1" density="0" rgba="0.752941 0.752941 0.752941 1" mesh="elbowLeft" />
                    <!-- # <geom type="mesh" rgba="0.752941 0.752941 0.752941 1" mesh="elbowLeft" /> -->
                    <body name="wristYawLeft" pos="-0.025 0.0285 -0.0729">
                      <inertial pos="-0.00204137 0.00010627 -0.0921678" quat="0.999621 -0.00660845 -0.00776879 -0.0255601" mass="0.955879" diaginertia="0.002562 0.00250145 0.000550223" />
                      <!-- <joint name="wristYaw_Left" pos="0 0 0" axis="0 0 1" range="-2.67 2.67" actuatorfrcrange="-6.4 6.4" /> -->
                      <geom type="mesh" contype="0" conaffinity="0" group="1" density="0" rgba="0.752941 0.752941 0.752941 1" mesh="wristYawLeft" />
                      <geom size="0.038 0.10" pos="0 0 -0.10" type="cylinder" />
                      <!-- <geom type="mesh" rgba="0.752941 0.752941 0.752941 1" mesh="wristYawLeft" /> -->
                      <body name="wristPitchLeft" pos="0 0 -0.2017">
                        <inertial pos="-0.00017582 0.00166098 -2.773e-05" quat="0.498275 0.501712 -0.500227 0.499779" mass="0.119635" diaginertia="3.97702e-05 3.35901e-05 2.68997e-05" />
                        <!-- <joint name="wristPitch_Left" pos="0 0 0" axis="0 1 0" range="-0.96 0.96" actuatorfrcrange="-6.4 6.4" /> -->
                        <geom type="mesh" contype="0" conaffinity="0" group="1" density="0" rgba="1 1 1 1" mesh="wristPitchLeft" />
                        <geom type="mesh" rgba="1 1 1 1" mesh="wristPitchLeft" />
                        <body name="wristRollLeft">
                          <inertial pos="-0.00027229 0.00864497 -0.0662702" quat="0.743139 -0.0248702 0.0370789 0.667646" mass="0.357497" diaginertia="0.000432717 0.000318933 0.0001829" />
                          <!-- <joint name="wristRoll_Left" pos="0 0 0" axis="1 0 0" range="-0.96 0.96" actuatorfrcrange="-6.4 6.4" /> -->
                          <geom type="mesh" contype="0" conaffinity="0" group="1" density="0" rgba="0.752941 0.752941 0.752941 1" mesh="wristRollLeft" />
                          <geom type="mesh" rgba="0.752941 0.752941 0.752941 1" mesh="wristRollLeft" />
                          <body name="L_thumb_proximal_base" pos="0.0245 -0.01 -0.047">
                            <inertial pos="0.00431634 0.00026726 -0.00141885" quat="0.402129 0.420407 0.428718 0.691196" mass="0.0089319" diaginertia="5.80786e-07 4.69278e-07 2.69935e-07" />
                            <!-- <joint name="L_thumb_MCP_joint1" pos="0 0 0" axis="0 0 -1" range="0 1.1" actuatorfrcrange="-1 1" /> -->
                            <geom type="mesh" contype="0" conaffinity="0" group="1" density="0" rgba="0.752941 0.752941 0.752941 1" mesh="L_thumb_proximal_base" />
                            <geom type="mesh" rgba="0.752941 0.752941 0.752941 1" mesh="L_thumb_proximal_base" />
                            <body name="L_thumb_proximal" pos="0.011954 -0.00104968 0" quat="0.999041 0 0 -0.0437786">
                              <inertial pos="0.0236969 0 -0.0146724" quat="0.655148 0.266048 0.266048 0.655148" mass="0.0615843" diaginertia="2.013e-05 1.73022e-05 5.79777e-06" />
                              <!-- <joint name="L_thumb_MCP_joint2" pos="0 0 0" axis="0 1 0" range="0 0.5" actuatorfrcrange="-1 1" /> -->
                              <geom type="mesh" contype="0" conaffinity="0" group="1" density="0" rgba="0.752941 0.752941 0.752941 1" mesh="L_thumb_proximal" />
                              <geom type="mesh" rgba="0.752941 0.752941 0.752941 1" mesh="L_thumb_proximal" />
                              <body name="L_thumb_intermediate" pos="0.0442886 0 -0.0376633">
                                <inertial pos="0.00973134 0 -0.00266466" quat="0.681637 0.188072 0.188072 0.681637" mass="0.0153834" diaginertia="1.72e-06 1.65294e-06 7.67055e-07" />
                                <!-- <joint name="L_thumb_PIP_joint" pos="0 0 0" axis="0 1 0" range="0 1" actuatorfrcrange="-1 1" /> -->
                                <geom type="mesh" contype="0" conaffinity="0" group="1" density="0" rgba="0.752941 0.752941 0.752941 1" mesh="L_thumb_intermediate" />
                                <geom type="mesh" rgba="0.752941 0.752941 0.752941 1" mesh="L_thumb_intermediate" />
                                <body name="L_thumb_distal" pos="0.0164679 0 -0.0154615">
                                  <inertial pos="0.00714221 -1.54e-06 -0.00689404" quat="0.967006 0 0.254755 0" mass="0.0104374" diaginertia="8.73238e-07 8.6e-07 4.06762e-07" />
                                  <!-- <joint name="L_thumb_DIP_joint" pos="0 0 0" axis="0 1 0" range="0 1.2" actuatorfrcrange="-1 1" /> -->
                                  <geom type="mesh" contype="0" conaffinity="0" group="1" density="0" rgba="0.752941 0.752941 0.752941 1" mesh="L_thumb_distal" />
                                  <geom type="mesh" rgba="0.752941 0.752941 0.752941 1" mesh="L_thumb_distal" />
                                </body>
                              </body>
                            </body>
                          </body>
                          <body name="L_index_proximal" pos="0.026942 0.0095 -0.114975" quat="0.999657 0 -0.0261769 0">
                            <inertial pos="0 0.00199817 -0.0131171" quat="0.707089 0.00501356 -0.00501356 0.707089" mass="0.0145411" diaginertia="1.95028e-06 1.95e-06 5.39716e-07" />
                            <!-- <joint name="L_index_MCP_joint" pos="0 0 0" axis="-1 0 0" range="0 1.7" actuatorfrcrange="-1 1" /> -->
                            <geom type="mesh" contype="0" conaffinity="0" group="1" density="0" rgba="0.752941 0.752941 0.752941 1" mesh="L_index_proximal" />
                            <geom type="mesh" rgba="0.752941 0.752941 0.752941 1" mesh="L_index_proximal" />
                            <body name="L_index_distal" pos="0 -0.00111269 -0.0319806">
                              <inertial pos="0 0.00168954 -0.0153694" quat="0.996466 0.0839918 0 0" mass="0.00905901" diaginertia="1.73e-06 1.72245e-06 2.07554e-07" />
                              <!-- <joint name="L_index_DIP_joint" pos="0 0 0" axis="-1 0 0" range="0 1.6" actuatorfrcrange="-1 1" /> -->
                              <geom type="mesh" contype="0" conaffinity="0" group="1" density="0" rgba="0.752941 0.752941 0.752941 1" mesh="L_index_distal" />
                              <geom type="mesh" rgba="0.752941 0.752941 0.752941 1" mesh="L_index_distal" />
                            </body>
                          </body>
                          <body name="L_middle_proximal" pos="0.008 0.0145 -0.128">
                            <inertial pos="0 0.00115546 -0.0133419" quat="0.999362 0.0357184 0 0" mass="0.013131" diaginertia="1.94e-06 1.93716e-06 5.32843e-07" />
                            <!-- <joint name="L_middle_MCP_joint" pos="0 0 0" axis="-1 0 0" range="0 1.7" actuatorfrcrange="-1 1" /> -->
                            <geom type="mesh" contype="0" conaffinity="0" group="1" density="0" rgba="0.752941 0.752941 0.752941 1" mesh="L_middle_proximal" />
                            <geom type="mesh" rgba="0.752941 0.752941 0.752941 1" mesh="L_middle_proximal" />
                            <body name="L_middle_distal" pos="0 -0.00293735 -0.0318649">
                              <inertial pos="0 -3.933e-05 -0.0154619" quat="0.990386 0.138332 0 0" mass="0.00905901" diaginertia="1.73e-06 1.72396e-06 2.06037e-07" />
                              <!-- <joint name="L_middle_DIP_joint" pos="0 0 0" axis="-1 0 0" range="0 1.6" actuatorfrcrange="-1 1" /> -->
                              <geom type="mesh" contype="0" conaffinity="0" group="1" density="0" rgba="0.752941 0.752941 0.752941 1" mesh="L_middle_distal" />
                              <geom type="mesh" rgba="0.752941 0.752941 0.752941 1" mesh="L_middle_distal" />
                            </body>
                          </body>
                          <body name="L_ring_proximal" pos="-0.010942 0.0095 -0.119975" quat="0.999657 0 0.0261769 0">
                            <inertial pos="-3.95e-06 0.00199338 -0.0131311" quat="0.707089 0.00501356 -0.00501356 0.707089" mass="0.0145411" diaginertia="1.95028e-06 1.95e-06 5.39716e-07" />
                            <!-- <joint name="L_ring_MCP_joint" pos="0 0 0" axis="-1 0 0" range="0 1.7" actuatorfrcrange="-1 1" /> -->
                            <geom type="mesh" contype="0" conaffinity="0" group="1" density="0" rgba="0.752941 0.752941 0.752941 1" mesh="L_ring_proximal" />
                            <geom type="mesh" rgba="0.752941 0.752941 0.752941 1" mesh="L_ring_proximal" />
                            <body name="L_ring_distal" pos="0 -0.00111269 -0.0319806">
                              <inertial pos="0 0.00168954 -0.0153694" quat="0.996466 0.0839918 0 0" mass="0.00905901" diaginertia="1.73e-06 1.72245e-06 2.07554e-07" />
                              <!-- <joint name="L_ring_DIP_joint" pos="0 0 0" axis="-1 0 0" range="0 1.6" actuatorfrcrange="-1 1" /> -->
                              <geom type="mesh" contype="0" conaffinity="0" group="1" density="0" rgba="0.752941 0.752941 0.752941 1" mesh="L_ring_distal" />
                              <geom type="mesh" rgba="0.752941 0.752941 0.752941 1" mesh="L_ring_distal" />
                            </body>
                          </body>
                          <body name="L_pinky_proximal" pos="-0.0301936 0.0045 -0.112866" quat="0.998135 0 0.0610485 0">
                            <inertial pos="0 0.00191043 -0.0132257" quat="0.707089 0.00501356 -0.00501356 0.707089" mass="0.013131" diaginertia="1.94028e-06 1.94e-06 5.29716e-07" />
                            <!-- <joint name="L_pinky_MCP_joint" pos="0 0 0" axis="-1 0 0" range="0 1.7" actuatorfrcrange="-1 1" /> -->
                            <geom type="mesh" contype="0" conaffinity="0" group="1" density="0" rgba="0.752941 0.752941 0.752941 1" mesh="L_pinky_proximal" />
                            <geom type="mesh" rgba="0.752941 0.752941 0.752941 1" mesh="L_pinky_proximal" />
                            <body name="L_pinky_distal" pos="0 -0.00111269 -0.0319806">
                              <inertial pos="1.99e-06 0.00260409 -0.0109991" quat="0.997444 0.0714519 0 0" mass="0.00693901" diaginertia="8.6e-07 8.54401e-07 1.45599e-07" />
                              <!-- <joint name="L_pinky_DIP_joint" pos="0 0 0" axis="-1 0 0" range="0 1.6" actuatorfrcrange="-1 1" /> -->
                              <geom type="mesh" contype="0" conaffinity="0" group="1" density="0" rgba="0.752941 0.752941 0.752941 1" mesh="L_pinky_distal" />
                              <geom type="mesh" rgba="0.752941 0.752941 0.752941 1" mesh="L_pinky_distal" />
                            </body>
                          </body>
                        </body>
                      </body>
                    </body>
                  </body>
                </body>
              </body>
            </body>
            <body name="shoulderPitchRight" pos="0 -0.165094 0.25923" quat="0.984808 -0.173648 0 0">
              <inertial pos="0.00536737 -0.0269397 0.00010693" quat="-0.0515608 0.702788 0.055363 0.707365" mass="0.216487" diaginertia="0.000381339 0.000323121 0.00018756" />
              <joint name="shoulderPitch_Right" pos="0 0 0" axis="0 1 0" range="-3.613 2.042" actuatorfrcrange="-65 65" />
              <geom type="mesh" contype="0" conaffinity="0" group="1" density="0" rgba="1 1 1 1" mesh="shoulderPitchRight" />
              <geom size="0.035 0.04" pos="0 0 0" quat="0.707105 0 0.707108 0" type="cylinder" />
              <!-- <geom type="mesh" rgba="1 1 1 1" mesh="shoulderPitchRight" /> -->
              <body name="shoulderRollRight" pos="0.0362 -0.0435 0" quat="0.984808 0.173648 0 0">
                <inertial pos="-0.0342995 -0.00987424 -0.0157184" quat="0.928314 0.252353 -0.0795949 0.26118" mass="1.08875" diaginertia="0.00170392 0.001678 0.000675842" />
                <joint name="shoulderRoll_Right" pos="0 0 0" axis="1 0 0" range="-2.793 0.628" actuatorfrcrange="-65 65" />
                <geom type="mesh" contype="0" conaffinity="0" group="1" density="0" rgba="0.752941 0.752941 0.752941 1" mesh="shoulderRollRight" />
                <!-- <geom type="mesh" rgba="0.752941 0.752941 0.752941 1" mesh="shoulderRollRight" /> -->
                <body name="shoulderYawRight" pos="-0.0362 -0.034 -0.0797">
                  <inertial pos="-0.00051403 0.00046316 -0.0619299" quat="0.999913 -0.00947141 -0.00876739 -0.00265779" mass="0.901393" diaginertia="0.0032861 0.00317291 0.000574074" />
                  <joint name="shoulderYaw_Right" pos="0 0 0" axis="0 0 1" range="-2.583 2.583" actuatorfrcrange="-65 65" />
                  <geom type="mesh" contype="0" conaffinity="0" group="1" density="0" rgba="1 1 1 1" mesh="shoulderYawRight" />
                  <geom size="0.03 0.075" pos="0 0 -0.08" type="cylinder" />
                  <!-- <geom type="mesh" rgba="1 1 1 1" mesh="shoulderYawRight" /> -->
                  <body name="elbowRight" pos="0 0.0285 -0.18295">
                    <inertial pos="-0.0140891 -0.0292958 -0.0253475" quat="0.405211 -0.22003 -0.0882783 0.882948" mass="0.917707" diaginertia="0.00112054 0.00108207 0.000458081" />
                    <joint name="elbow_Right" pos="0 0 0" axis="0 1 0" range="-2.496 0.209" actuatorfrcrange="-30 30" />
                    <geom type="mesh" contype="0" conaffinity="0" group="1" density="0" rgba="0.752941 0.752941 0.752941 1" mesh="elbowRight" />
                    <!-- <geom type="mesh" rgba="0.752941 0.752941 0.752941 1" mesh="elbowRight" /> -->
                    <body name="wristYawRight" pos="-0.025 -0.0285 -0.0729">
                      <inertial pos="-0.00202981 -0.00013146 -0.0921689" quat="0.999613 0.00676608 -0.00779174 0.0258466" mass="0.955878" diaginertia="0.00256155 0.0025005 0.000549744" />
                      <!-- <joint name="wristYaw_Right" pos="0 0 0" axis="0 0 1" range="-2.67 2.67" actuatorfrcrange="-6.4 6.4" /> -->
                      <geom type="mesh" contype="0" conaffinity="0" group="1" density="0" rgba="0.752941 0.752941 0.752941 1" mesh="wristYawRight" />
                      <!-- <geom type="mesh" rgba="0.752941 0.752941 0.752941 1" mesh="wristYawRight" /> -->
                      <geom size="0.038 0.10" pos="0 0 -0.10" type="cylinder" />
                      <body name="wristPitchRight" pos="0 0 -0.2017">
                        <inertial pos="-0.0001758 0.00166098 -2.773e-05" quat="0.498275 0.501712 -0.500227 0.499779" mass="0.119635" diaginertia="3.97702e-05 3.35901e-05 2.68997e-05" />
                        <!-- <joint name="wristPitch_Right" pos="0 0 0" axis="0 1 0" range="-0.96 0.96" actuatorfrcrange="-6.4 6.4" /> -->
                        <geom type="mesh" contype="0" conaffinity="0" group="1" density="0" rgba="1 1 1 1" mesh="wristPitchRight" />
                        <geom type="mesh" rgba="1 1 1 1" mesh="wristPitchRight" />
                        <body name="wristRollRight">
                          <inertial pos="-0.00030616 -0.00861825 -0.0663443" quat="0.666961 0.0378803 -0.0231418 0.743769" mass="0.358155" diaginertia="0.000433212 0.000319556 0.000183031" />
                          <!-- <joint name="wristRoll_Right" pos="0 0 0" axis="1 0 0" range="-0.96 0.96" actuatorfrcrange="-6.4 6.4" /> -->
                          <geom type="mesh" contype="0" conaffinity="0" group="1" density="0" rgba="0.752941 0.752941 0.752941 1" mesh="wristRollRight" />
                          <geom type="mesh" rgba="0.752941 0.752941 0.752941 1" mesh="wristRollRight" />
                          <body name="R_thumb_proximal_base" pos="0.0245 0.01 -0.047">
                            <inertial pos="0.00431634 -0.00026726 -0.00141884" quat="0.691196 0.428718 0.420407 0.402129" mass="0.0089319" diaginertia="5.80786e-07 4.69278e-07 2.69935e-07" />
                            <!-- <joint name="R_thumb_MCP_joint1" pos="0 0 0" axis="0 0 1" range="0 1.1" actuatorfrcrange="-1 1" /> -->
                            <geom type="mesh" contype="0" conaffinity="0" group="1" density="0" rgba="0.752941 0.752941 0.752941 1" mesh="R_thumb_proximal_base" />
                            <geom type="mesh" rgba="0.752941 0.752941 0.752941 1" mesh="R_thumb_proximal_base" />
                            <body name="R_thumb_proximal" pos="0.011954 0.00104968 0" quat="0.999041 0 0 0.0437786">
                              <inertial pos="0.0236968 0 -0.0146723" quat="0.655148 0.266048 0.266048 0.655148" mass="0.0615843" diaginertia="2.013e-05 1.73022e-05 5.79777e-06" />
                              <!-- <joint name="R_thumb_MCP_joint2" pos="0 0 0" axis="0 1 0" range="0 0.5" actuatorfrcrange="-1 1" /> -->
                              <geom type="mesh" contype="0" conaffinity="0" group="1" density="0" rgba="0.752941 0.752941 0.752941 1" mesh="R_thumb_proximal" />
                              <geom type="mesh" rgba="0.752941 0.752941 0.752941 1" mesh="R_thumb_proximal" />
                              <body name="R_thumb_intermediate" pos="0.0442886 0 -0.0376633">
                                <inertial pos="0.00973134 0 -0.00266467" quat="0.681637 0.188072 0.188072 0.681637" mass="0.0153834" diaginertia="1.72e-06 1.65294e-06 7.67055e-07" />
                                <!-- <joint name="R_thumb_PIP_joint" pos="0 0 0" axis="0 1 0" range="0 1" actuatorfrcrange="-1 1" /> -->
                                <geom type="mesh" contype="0" conaffinity="0" group="1" density="0" rgba="0.752941 0.752941 0.752941 1" mesh="R_thumb_intermediate" />
                                <geom type="mesh" rgba="0.752941 0.752941 0.752941 1" mesh="R_thumb_intermediate" />
                                <body name="R_thumb_distal" pos="0.0164679 0 -0.0154615">
                                  <inertial pos="0.00714151 1.39e-06 -0.00689413" quat="0.967006 0 0.254755 0" mass="0.0104374" diaginertia="8.73238e-07 8.6e-07 4.06762e-07" />
                                  <!-- <joint name="R_thumb_DIP_joint" pos="0 0 0" axis="0 1 0" range="0 1.2" actuatorfrcrange="-1 1" /> -->
                                  <geom type="mesh" contype="0" conaffinity="0" group="1" density="0" rgba="0.752941 0.752941 0.752941 1" mesh="R_thumb_distal" />
                                  <geom type="mesh" rgba="0.752941 0.752941 0.752941 1" mesh="R_thumb_distal" />
                                </body>
                              </body>
                            </body>
                          </body>
                          <body name="R_index_proximal" pos="0.026942 -0.0095 -0.114975" quat="0.999657 0 -0.0261769 0">
                            <inertial pos="0 -0.0019982 -0.0131171" quat="0.707089 -0.00501356 0.00501356 0.707089" mass="0.0145412" diaginertia="1.95028e-06 1.95e-06 5.39716e-07" />
                            <!-- <joint name="R_index_MCP_joint" pos="0 0 0" axis="1 0 0" range="0 1.7" actuatorfrcrange="-1 1" /> -->
                            <geom type="mesh" contype="0" conaffinity="0" group="1" density="0" rgba="0.752941 0.752941 0.752941 1" mesh="R_index_proximal" />
                            <geom type="mesh" rgba="0.752941 0.752941 0.752941 1" mesh="R_index_proximal" />
                            <body name="R_index_distal" pos="0 0.00111269 -0.0319806">
                              <inertial pos="0 -0.00168936 -0.0153697" quat="0.996466 -0.0839918 0 0" mass="0.00905901" diaginertia="1.73e-06 1.72245e-06 2.07554e-07" />
                              <!-- <joint name="R_index_DIP_joint" pos="0 0 0" axis="1 0 0" range="0 1.6" actuatorfrcrange="-1 1" /> -->
                              <geom type="mesh" contype="0" conaffinity="0" group="1" density="0" rgba="0.752941 0.752941 0.752941 1" mesh="R_index_distal" />
                              <geom type="mesh" rgba="0.752941 0.752941 0.752941 1" mesh="R_index_distal" />
                            </body>
                          </body>
                          <body name="R_middle_proximal" pos="0.008 -0.0145 -0.128">
                            <inertial pos="0 -0.00115549 -0.0133419" quat="0.999362 -0.0357184 0 0" mass="0.0131311" diaginertia="1.94e-06 1.93716e-06 5.32843e-07" />
                            <!-- <joint name="R_middle_MCP_joint" pos="0 0 0" axis="1 0 0" range="0 1.7" actuatorfrcrange="-1 1" /> -->
                            <geom type="mesh" contype="0" conaffinity="0" group="1" density="0" rgba="0.752941 0.752941 0.752941 1" mesh="R_middle_proximal" />
                            <geom type="mesh" rgba="0.752941 0.752941 0.752941 1" mesh="R_middle_proximal" />
                            <body name="R_middle_distal" pos="0 0.00293735 -0.0318649">
                              <inertial pos="0 3.955e-05 -0.0154622" quat="0.990386 -0.138332 0 0" mass="0.00905901" diaginertia="1.73e-06 1.72396e-06 2.06037e-07" />
                              <!-- <joint name="R_middle_DIP_joint" pos="0 0 0" axis="1 0 0" range="0 1.6" actuatorfrcrange="-1 1" /> -->
                              <geom type="mesh" contype="0" conaffinity="0" group="1" density="0" rgba="0.752941 0.752941 0.752941 1" mesh="R_middle_distal" />
                              <geom type="mesh" rgba="0.752941 0.752941 0.752941 1" mesh="R_middle_distal" />
                            </body>
                          </body>
                          <body name="R_ring_proximal" pos="-0.010942 -0.0095 -0.119975" quat="0.999657 0 0.0261769 0">
                            <inertial pos="0 -0.0019982 -0.0131171" quat="0.707089 -0.00501356 0.00501356 0.707089" mass="0.0145412" diaginertia="1.95028e-06 1.95e-06 5.39716e-07" />
                            <!-- <joint name="R_ring_MCP_joint" pos="0 0 0" axis="1 0 0" range="0 1.7" actuatorfrcrange="-1 1" /> -->
                            <geom type="mesh" contype="0" conaffinity="0" group="1" density="0" rgba="0.752941 0.752941 0.752941 1" mesh="R_ring_proximal" />
                            <geom type="mesh" rgba="0.752941 0.752941 0.752941 1" mesh="R_ring_proximal" />
                            <body name="R_ring_distal" pos="0 0.00111269 -0.0319806">
                              <inertial pos="0 -0.00168936 -0.0153697" quat="0.996466 -0.0839918 0 0" mass="0.00905901" diaginertia="1.73e-06 1.72245e-06 2.07554e-07" />
                              <!-- <joint name="R_ring_DIP_joint" pos="0 0 0" axis="1 0 0" range="0 1.6" actuatorfrcrange="-1 1" /> -->
                              <geom type="mesh" contype="0" conaffinity="0" group="1" density="0" rgba="0.752941 0.752941 0.752941 1" mesh="R_ring_distal" />
                              <geom type="mesh" rgba="0.752941 0.752941 0.752941 1" mesh="R_ring_distal" />
                            </body>
                          </body>
                          <body name="R_pinky_proximal" pos="-0.0301936 -0.0045 -0.112866" quat="0.998135 0 0.0610485 0">
                            <inertial pos="0 -0.00191046 -0.0132258" quat="0.707089 -0.00501356 0.00501356 0.707089" mass="0.0131311" diaginertia="1.94028e-06 1.94e-06 5.29716e-07" />
                            <!-- <joint name="R_pinky_MCP_joint" pos="0 0 0" axis="1 0 0" range="0 1.7" actuatorfrcrange="-1 1" /> -->
                            <geom type="mesh" contype="0" conaffinity="0" group="1" density="0" rgba="0.752941 0.752941 0.752941 1" mesh="R_pinky_proximal" />
                            <geom type="mesh" rgba="0.752941 0.752941 0.752941 1" mesh="R_pinky_proximal" />
                            <body name="R_pinky_distal" pos="0 0.00111269 -0.0319806">
                              <inertial pos="2.01e-06 -0.00260417 -0.0109989" quat="0.997444 -0.0714519 0 0" mass="0.00693901" diaginertia="8.6e-07 8.54401e-07 1.45599e-07" />
                              <!-- <joint name="R_pinky_DIP_joint" pos="0 0 0" axis="1 0 0" range="0 1.6" actuatorfrcrange="-1 1" /> -->
                              <geom type="mesh" contype="0" conaffinity="0" group="1" density="0" rgba="0.752941 0.752941 0.752941 1" mesh="R_pinky_distal" />
                              <geom type="mesh" rgba="0.752941 0.752941 0.752941 1" mesh="R_pinky_distal" />
                            </body>
                          </body>
                        </body>
                      </body>
                    </body>
                  </body>
                </body>
              </body>
            </body>
          </body>
        </body>
      </body>
      <site name="imu" pos="0 0 0" />
    </body>
  </worldbody>
  <sensor>
    <gyro name="imu_ang_vel" site="imu"/>
    <velocimeter name="imu_lin_vel" site="imu"/>
    <accelerometer name="imu_lin_acc" site="imu"/>
    <subtreeangmom name="root_angmom" body="pelvis"/>
    <jointpos name="pos_hipPitch_Left" joint="hipPitch_Left" />
    <jointpos name="pos_hipRoll_Left" joint="hipRoll_Left" />
    <jointpos name="pos_hipYaw_Left" joint="hipYaw_Left" />
    <jointpos name="pos_kneePitch_Left" joint="kneePitch_Left" />
    <jointpos name="pos_anklePitch_Left" joint="anklePitch_Left" />
    <jointpos name="pos_ankleRoll_Left" joint="ankleRoll_Left" />
    <jointpos name="pos_hipPitch_Right" joint="hipPitch_Right" />
    <jointpos name="pos_hipRoll_Right" joint="hipRoll_Right" />
    <jointpos name="pos_hipYaw_Right" joint="hipYaw_Right" />
    <jointpos name="pos_kneePitch_Right" joint="kneePitch_Right" />
    <jointpos name="pos_anklePitch_Right" joint="anklePitch_Right" />
    <jointpos name="pos_ankleRoll_Right" joint="ankleRoll_Right" />
    <jointpos name="pos_waistRoll" joint="waistRoll" />
    <jointpos name="pos_waistPitch" joint="waistPitch" />
    <jointpos name="pos_waistYaw" joint="waistYaw" />
    <jointpos name="pos_shoulderPitch_Left" joint="shoulderPitch_Left" />
    <jointpos name="pos_shoulderRoll_Left" joint="shoulderRoll_Left" />
    <jointpos name="pos_shoulderYaw_Left" joint="shoulderYaw_Left" />
    <jointpos name="pos_elbow_Left" joint="elbow_Left" />
    <!-- <jointpos name="pos_wristYaw_Left" joint="wristYaw_Left" />
    <jointpos name="pos_wristPitch_Left" joint="wristPitch_Left" />
    <jointpos name="pos_wristRoll_Left" joint="wristRoll_Left" />
    <jointpos name="pos_L_thumb_MCP_joint1" joint="L_thumb_MCP_joint1" />
    <jointpos name="pos_L_thumb_MCP_joint2" joint="L_thumb_MCP_joint2" />
    <jointpos name="pos_L_thumb_PIP_joint" joint="L_thumb_PIP_joint" />
    <jointpos name="pos_L_thumb_DIP_joint" joint="L_thumb_DIP_joint" />
    <jointpos name="pos_L_index_MCP_joint" joint="L_index_MCP_joint" />
    <jointpos name="pos_L_index_DIP_joint" joint="L_index_DIP_joint" />
    <jointpos name="pos_L_middle_MCP_joint" joint="L_middle_MCP_joint" />
    <jointpos name="pos_L_middle_DIP_joint" joint="L_middle_DIP_joint" />
    <jointpos name="pos_L_ring_MCP_joint" joint="L_ring_MCP_joint" />
    <jointpos name="pos_L_ring_DIP_joint" joint="L_ring_DIP_joint" />
    <jointpos name="pos_L_pinky_MCP_joint" joint="L_pinky_MCP_joint" />
    <jointpos name="pos_L_pinky_DIP_joint" joint="L_pinky_DIP_joint" /> -->
    <jointpos name="pos_shoulderPitch_Right" joint="shoulderPitch_Right" />
    <jointpos name="pos_shoulderRoll_Right" joint="shoulderRoll_Right" />
    <jointpos name="pos_shoulderYaw_Right" joint="shoulderYaw_Right" />
    <jointpos name="pos_elbow_Right" joint="elbow_Right" />
    <!-- <jointpos name="pos_wristYaw_Right" joint="wristYaw_Right" />
    <jointpos name="pos_wristPitch_Right" joint="wristPitch_Right" />
    <jointpos name="pos_wristRoll_Right" joint="wristRoll_Right" />
    <jointpos name="pos_R_thumb_MCP_joint1" joint="R_thumb_MCP_joint1" />
    <jointpos name="pos_R_thumb_MCP_joint2" joint="R_thumb_MCP_joint2" />
    <jointpos name="pos_R_thumb_PIP_joint" joint="R_thumb_PIP_joint" />
    <jointpos name="pos_R_thumb_DIP_joint" joint="R_thumb_DIP_joint" />
    <jointpos name="pos_R_index_MCP_joint" joint="R_index_MCP_joint" />
    <jointpos name="pos_R_index_DIP_joint" joint="R_index_DIP_joint" />
    <jointpos name="pos_R_middle_MCP_joint" joint="R_middle_MCP_joint" />
    <jointpos name="pos_R_middle_DIP_joint" joint="R_middle_DIP_joint" />
    <jointpos name="pos_R_ring_MCP_joint" joint="R_ring_MCP_joint" />
    <jointpos name="pos_R_ring_DIP_joint" joint="R_ring_DIP_joint" />
    <jointpos name="pos_R_pinky_MCP_joint" joint="R_pinky_MCP_joint" />
    <jointpos name="pos_R_pinky_DIP_joint" joint="R_pinky_DIP_joint" /> -->
    <jointvel name="vel_hipPitch_Left" joint="hipPitch_Left" />
    <jointvel name="vel_hipRoll_Left" joint="hipRoll_Left" />
    <jointvel name="vel_hipYaw_Left" joint="hipYaw_Left" />
    <jointvel name="vel_kneePitch_Left" joint="kneePitch_Left" />
    <jointvel name="vel_anklePitch_Left" joint="anklePitch_Left" />
    <jointvel name="vel_ankleRoll_Left" joint="ankleRoll_Left" />
    <jointvel name="vel_hipPitch_Right" joint="hipPitch_Right" />
    <jointvel name="vel_hipRoll_Right" joint="hipRoll_Right" />
    <jointvel name="vel_hipYaw_Right" joint="hipYaw_Right" />
    <jointvel name="vel_kneePitch_Right" joint="kneePitch_Right" />
    <jointvel name="vel_anklePitch_Right" joint="anklePitch_Right" />
    <jointvel name="vel_ankleRoll_Right" joint="ankleRoll_Right" />
    <jointvel name="vel_waistRoll" joint="waistRoll" />
    <jointvel name="vel_waistPitch" joint="waistPitch" />
    <jointvel name="vel_waistYaw" joint="waistYaw" />
    <jointvel name="vel_shoulderPitch_Left" joint="shoulderPitch_Left" />
    <jointvel name="vel_shoulderRoll_Left" joint="shoulderRoll_Left" />
    <jointvel name="vel_shoulderYaw_Left" joint="shoulderYaw_Left" />
    <jointvel name="vel_elbow_Left" joint="elbow_Left" />
    <!-- <jointvel name="vel_wristYaw_Left" joint="wristYaw_Left" />
    <jointvel name="vel_wristPitch_Left" joint="wristPitch_Left" />
    <jointvel name="vel_wristRoll_Left" joint="wristRoll_Left" />
    <jointvel name="vel_L_thumb_MCP_joint1" joint="L_thumb_MCP_joint1" />
    <jointvel name="vel_L_thumb_MCP_joint2" joint="L_thumb_MCP_joint2" />
    <jointvel name="vel_L_thumb_PIP_joint" joint="L_thumb_PIP_joint" />
    <jointvel name="vel_L_thumb_DIP_joint" joint="L_thumb_DIP_joint" />
    <jointvel name="vel_L_index_MCP_joint" joint="L_index_MCP_joint" />
    <jointvel name="vel_L_index_DIP_joint" joint="L_index_DIP_joint" />
    <jointvel name="vel_L_middle_MCP_joint" joint="L_middle_MCP_joint" />
    <jointvel name="vel_L_middle_DIP_joint" joint="L_middle_DIP_joint" />
    <jointvel name="vel_L_ring_MCP_joint" joint="L_ring_MCP_joint" />
    <jointvel name="vel_L_ring_DIP_joint" joint="L_ring_DIP_joint" />
    <jointvel name="vel_L_pinky_MCP_joint" joint="L_pinky_MCP_joint" />
    <jointvel name="vel_L_pinky_DIP_joint" joint="L_pinky_DIP_joint" /> -->
    <jointvel name="vel_shoulderPitch_Right" joint="shoulderPitch_Right" />
    <jointvel name="vel_shoulderRoll_Right" joint="shoulderRoll_Right" />
    <jointvel name="vel_shoulderYaw_Right" joint="shoulderYaw_Right" />
    <jointvel name="vel_elbow_Right" joint="elbow_Right" />
    <!-- <jointvel name="vel_wristYaw_Right" joint="wristYaw_Right" />
    <jointvel name="vel_wristPitch_Right" joint="wristPitch_Right" />
    <jointvel name="vel_wristRoll_Right" joint="wristRoll_Right" />
    <jointvel name="vel_R_thumb_MCP_joint1" joint="R_thumb_MCP_joint1" />
    <jointvel name="vel_R_thumb_MCP_joint2" joint="R_thumb_MCP_joint2" />
    <jointvel name="vel_R_thumb_PIP_joint" joint="R_thumb_PIP_joint" />
    <jointvel name="vel_R_thumb_DIP_joint" joint="R_thumb_DIP_joint" />
    <jointvel name="vel_R_index_MCP_joint" joint="R_index_MCP_joint" />
    <jointvel name="vel_R_index_DIP_joint" joint="R_index_DIP_joint" />
    <jointvel name="vel_R_middle_MCP_joint" joint="R_middle_MCP_joint" />
    <jointvel name="vel_R_middle_DIP_joint" joint="R_middle_DIP_joint" />
    <jointvel name="vel_R_ring_MCP_joint" joint="R_ring_MCP_joint" />
    <jointvel name="vel_R_ring_DIP_joint" joint="R_ring_DIP_joint" />
    <jointvel name="vel_R_pinky_MCP_joint" joint="R_pinky_MCP_joint" />
    <jointvel name="vel_R_pinky_DIP_joint" joint="R_pinky_DIP_joint" /> -->
    <jointactuatorfrc name="force_hipPitch_Left" joint="hipPitch_Left" />
    <jointactuatorfrc name="force_hipRoll_Left" joint="hipRoll_Left" />
    <jointactuatorfrc name="force_hipYaw_Left" joint="hipYaw_Left" />
    <jointactuatorfrc name="force_kneePitch_Left" joint="kneePitch_Left" />
    <jointactuatorfrc name="force_anklePitch_Left" joint="anklePitch_Left" />
    <jointactuatorfrc name="force_ankleRoll_Left" joint="ankleRoll_Left" />
    <jointactuatorfrc name="force_hipPitch_Right" joint="hipPitch_Right" />
    <jointactuatorfrc name="force_hipRoll_Right" joint="hipRoll_Right" />
    <jointactuatorfrc name="force_hipYaw_Right" joint="hipYaw_Right" />
    <jointactuatorfrc name="force_kneePitch_Right" joint="kneePitch_Right" />
    <jointactuatorfrc name="force_anklePitch_Right" joint="anklePitch_Right" />
    <jointactuatorfrc name="force_ankleRoll_Right" joint="ankleRoll_Right" />
    <jointactuatorfrc name="force_waistRoll" joint="waistRoll" />
    <jointactuatorfrc name="force_waistPitch" joint="waistPitch" />
    <jointactuatorfrc name="force_waistYaw" joint="waistYaw" />
    <jointactuatorfrc name="force_shoulderPitch_Left" joint="shoulderPitch_Left" />
    <jointactuatorfrc name="force_shoulderRoll_Left" joint="shoulderRoll_Left" />
    <jointactuatorfrc name="force_shoulderYaw_Left" joint="shoulderYaw_Left" />
    <jointactuatorfrc name="force_elbow_Left" joint="elbow_Left" />
    <!-- <jointactuatorfrc name="force_wristYaw_Left" joint="wristYaw_Left" />
    <jointactuatorfrc name="force_wristPitch_Left" joint="wristPitch_Left" />
    <jointactuatorfrc name="force_wristRoll_Left" joint="wristRoll_Left" />
    <jointactuatorfrc name="force_L_thumb_MCP_joint1" joint="L_thumb_MCP_joint1" />
    <jointactuatorfrc name="force_L_thumb_MCP_joint2" joint="L_thumb_MCP_joint2" />
    <jointactuatorfrc name="force_L_thumb_PIP_joint" joint="L_thumb_PIP_joint" />
    <jointactuatorfrc name="force_L_thumb_DIP_joint" joint="L_thumb_DIP_joint" />
    <jointactuatorfrc name="force_L_index_MCP_joint" joint="L_index_MCP_joint" />
    <jointactuatorfrc name="force_L_index_DIP_joint" joint="L_index_DIP_joint" />
    <jointactuatorfrc name="force_L_middle_MCP_joint" joint="L_middle_MCP_joint" />
    <jointactuatorfrc name="force_L_middle_DIP_joint" joint="L_middle_DIP_joint" />
    <jointactuatorfrc name="force_L_ring_MCP_joint" joint="L_ring_MCP_joint" />
    <jointactuatorfrc name="force_L_ring_DIP_joint" joint="L_ring_DIP_joint" />
    <jointactuatorfrc name="force_L_pinky_MCP_joint" joint="L_pinky_MCP_joint" />
    <jointactuatorfrc name="force_L_pinky_DIP_joint" joint="L_pinky_DIP_joint" /> -->
    <jointactuatorfrc name="force_shoulderPitch_Right" joint="shoulderPitch_Right" />
    <jointactuatorfrc name="force_shoulderRoll_Right" joint="shoulderRoll_Right" />
    <jointactuatorfrc name="force_shoulderYaw_Right" joint="shoulderYaw_Right" />
    <jointactuatorfrc name="force_elbow_Right" joint="elbow_Right" />
    <!-- <jointactuatorfrc name="force_wristYaw_Right" joint="wristYaw_Right" />
    <jointactuatorfrc name="force_wristPitch_Right" joint="wristPitch_Right" />
    <jointactuatorfrc name="force_wristRoll_Right" joint="wristRoll_Right" />
    <jointactuatorfrc name="force_R_thumb_MCP_joint1" joint="R_thumb_MCP_joint1" />
    <jointactuatorfrc name="force_R_thumb_MCP_joint2" joint="R_thumb_MCP_joint2" />
    <jointactuatorfrc name="force_R_thumb_PIP_joint" joint="R_thumb_PIP_joint" />
    <jointactuatorfrc name="force_R_thumb_DIP_joint" joint="R_thumb_DIP_joint" />
    <jointactuatorfrc name="force_R_index_MCP_joint" joint="R_index_MCP_joint" />
    <jointactuatorfrc name="force_R_index_DIP_joint" joint="R_index_DIP_joint" />
    <jointactuatorfrc name="force_R_middle_MCP_joint" joint="R_middle_MCP_joint" />
    <jointactuatorfrc name="force_R_middle_DIP_joint" joint="R_middle_DIP_joint" />
    <jointactuatorfrc name="force_R_ring_MCP_joint" joint="R_ring_MCP_joint" />
    <jointactuatorfrc name="force_R_ring_DIP_joint" joint="R_ring_DIP_joint" />
    <jointactuatorfrc name="force_R_pinky_MCP_joint" joint="R_pinky_MCP_joint" />
    <jointactuatorfrc name="force_R_pinky_DIP_joint" joint="R_pinky_DIP_joint" /> -->
  </sensor>

  <!-- setup scene -->
  <statistic center="1.0 0.7 1.0" extent="0.8"/>
  <!-- <visual>
    <headlight diffuse="0.6 0.6 0.6" ambient="0.1 0.1 0.1" specular="0.9 0.9 0.9"/>
    <rgba haze="0.15 0.25 0.35 1"/>
    <global azimuth="-140" elevation="-20"/>
  </visual>
  <asset>
    <texture type="skybox" builtin="flat" rgb1="0 0 0" rgb2="0 0 0" width="512" height="3072"/>
    <texture type="2d" name="groundplane" builtin="checker" mark="edge" rgb1="0.2 0.3 0.4" rgb2="0.1 0.2 0.3" markrgb="0.8 0.8 0.8" width="300" height="300"/>
    <material name="groundplane" texture="groundplane" texuniform="true" texrepeat="5 5" reflectance="0.2"/>
  </asset>
  <worldbody>
    <light pos="1 0 3.5" dir="0 0 -1" directional="true"/>
    <geom name="floor" size="0 0 0.05" type="plane" material="groundplane"/>
  </worldbody> -->
  
</mujoco>